Workbook

Sheet Revenue
A1: Month | B1: Contract | C1: Description | D1: GAAP Overide Revenue Projection | E1: Ops Overide Revenue Projection | F1: Bonus Profit | G1: Anticipated Completion Date
A2: 45992 | B2: 21.2106 | C2: Sturgeon Electric - Ashlan Ave. Corridor | D2: 120553.54 | E2: 138609 | F2: 860.6 | G2: 46081
A3: 45992 | B3: 21.2304 | C3: City of Merced - Community Park 42 | D3: 10996796 | E3: 10996796 | F3: 955128 | G3: 46203
A4: 45992 | B4: 21.231 | C4: City of Porterville - Tule River Parkway Phase 3 | D4: 3543296.5 | E4: 3543296.5 | F4: 404137 | G4: 46053
A5: 45992 | B5: 21.2312 | C5: City of Fresno - Mariposa Plaza Renovation | D5: 2832730 | E5: 2832730 | F5: 157930 | G5: 46081
A6: 45992 | B6: 21.2314 | C6: G.L. Associates Bruno - Clovis VA Parking Expansion | D6: 1294297 | E6: 1294297 | F6: 0 | G6: TBD
A7: 45992 | B7: 21.2323 | C7: WM Lyles - Water Treatment Plant Replacement | D7: 1912857.8 | E7: 1912857.8 | F7: 506428 | G7: 46173
A8: 45992 | B8: 21.2407 | C8: City of Fresno - South Peach Park Project | D8: 9700445.1 | E8: 9700445.1 | F8: 282981.5 | G8: 46295
A9: 45992 | B9: 21.2408 | C9: A-C Electric Co. - Friant I.T.S. Phase 2 | D9: 130099.7 | E9: 130099.7 | F9: 29812 | G9: 46081
A10: 45992 | B10: 21.241 | C10: City of Fresno - Barstow and Bond Traffic Signal | D10: 1320507 | E10: 1320507 | F10: 155660.4 | G10: 46081
A11: 45992 | B11: 21.2411 | C11: City of Merced - Bob Hart Square Expansion | D11: 3460630.5 | E11: 3460630.5 | F11: 166402 | G11: 46265
A12: 45992 | B12: 21.2412 | C12: City of Merced - Main Street Directional (REBID) | D12: 1289873 | E12: 1289873 | F12: 248547.6 | G12: 46053
A13: 45992 | B13: 21.2502 | C13: HPS Mechanical - Well 7 TCP Mitigation Project | D13: 332999.4 | E13: 332999.4 | F13: 0 | G13: 46112
A14: 45992 | B14: 21.2503 | C14: City of Fresno - Dolores Huerta Park | D14: 9987006.4 | E14: 9987006.4 | F14: 183540 | G14: 46234
A15: 45992 | B15: 21.2504 | C15: A-C Electric Co. - Clovis Avenue Adaptive Traffic Signal Sychronization Project | D15: 168405 | E15: 168405 | F15: 0 | G15: 46142
A16: 45992 | B16: 21.2505 | C16: A-C Electric Co. - Reed Avenue and Reedley College Driveway Traffic Signal | D16: 218115 | E16: 218115 | F16: 0 | G16: 46112
A17: 45992 | B17: 21.2507 | C17: City of Fresno - Radio Park Renovation | D17: 9177239.8 | E17: 9177239.8 | F17: 0 | G17: 46418
A18: 45992 | B18: 21.2509 | C18: City of Sanger - Bethel Avenue and Almond Avenue Traffic Signal Improvements | D18: 699952 | E18: 699952 | F18: 0 | G18: 46203
A19: 45992 | B19: 20.2571 | C19: APC Yard Improvements - Equipment Building | D19: 0 | F19: -10673.67 | G19: 46053
A20: 45992 | B20: 20.2572 | C20: APC Yard Improvements - Ponding Basin | D20: 0 | F20: -1656.39 | G20: 46112
A21: 45992 | B21: 20.2573 | C21: APC Yard Improvements - Equipment Shed | D21: 0 | F21: -347.51 | G21: 46081
A22: 45992 | B22: 20.2574 | C22: APC Yard Improvements - Shop Storage | D22: 0 | F22: -2373.78 | G22: 46053
A23: 45992 | B23: 21.2307 | C23: Madera County - Ave 25 Bridge Replacement Proj. at Ash Slough | D23: 5192801.8 | E23: 5192801.8 | F23: 863269.01 | G23: 45838
A24: 45992 | B24: 21.2313 | C24: City of Kerman - Kerman Northwest Park | D24: 700013.94 | E24: 700013.94 | F24: 157867.49 | G24: 45961
A25: 45992 | B25: 21.2316 | C25: WM Lyles - Groundwater Blending & Arsenic Treatment Project | D25: 1603209.7 | E25: 1603209.7 | F25: 172112.29 | G25: 45838
A26: 45992 | B26: 21.2317 | C26: City of Fresno - Connecting the Winchell | D26: 1815311.4 | E26: 1815311.4 | F26: 255551.53 | G26: 45838
A27: 45992 | B27: 21.2322 | C27: A-C Electric Co. - Kaiser Fresno Modular MOB-Offsite | D27: 218864.46 | E27: 218864.46 | F27: 70831.34 | G27: 45838
A28: 45992 | B28: 21.2401 | C28: County of Tulare - M109 Over White River Bridge Replacement Project | D28: 5256236.8 | E28: 5256236.8 | F28: 1545733.5 | G28: 45838
A29: 45992 | B29: 21.2403 | C29: City of Fresno - Woodward & Roeding Tot Lots & ADA Accessibility Improvements | D29: 2001595.3 | E29: 2001595.3 | F29: 338795.39 | G29: 45838
A30: 45992 | B30: 21.2406 | C30: City of Fresno - BPMP Phase II | D30: 734312.72 | E30: 734312.72 | F30: 280244 | G30: 45777
A31: 45992 | B31: 21.2409 | C31: City of Merced - G Street Bridge Railing Repair | D31: 178520 | E31: 178520 | F31: 50426.74 | G31: 45838
A32: 45992 | B32: 21.2413 | C32: NESM - Amazon ADA Improvements | D32: 3650.84 | E32: 3650.84 | F32: 569.26 | G32: 45777
A33: 45992 | B33: 21.2501 | C33: C3 Electric - Lake and Sherwood Traffic Signal | D33: 134976.95 | E33: 134976.95 | F33: 11248.57 | G33: 46022
A34: 45992 | B34: 21.2506 | C34: Showtime Concrete, Inc. - Kaiser Permanente Cypress Charging Station | D34: 33252 | E34: 33252 | F34: 20381.02 | G34: 45869
... A39: 45992 | B39: 21.2593 | C39: NESM Intercompany L&E | D39: 2034.2 | E39: 2034.2 | F39: 138.34 | G39: 46022
A40: 45992 | B40: 20.252 | C40: APC Office Admin/Overhead | D40: 0 | F40: -417362.06 | G40: 46022
A41: 45992 | B41: 20.253 | C41: APC Yard/Building | D41: 0 | F41: -136442.7 | G41: 46022
A42: 45992 | B42: 20.254 | C42: APC Warranty Work | D42: 0 | F42: -4786.46 | G42: 46022
A43: 45992 | B43: 20.255 | C43: APC Legal | D43: 0 | F43: -7603.98 | G43: 46022
A44: 45992 | B44: 20.256 | C44: APC Estimating | D44: 0 | F44: -345355.21 | G44: 46022
...

Sheet Cost
A1: Month | B1: Job | C1: Job Desc | D1: GAAP Overide Cost Projection | E1: Ops Overide Cost Projection
A2: =Revenue!A2 -> 45992 | B2: =Revenue!B2 -> 21.2106 | C2: =Revenue!C2 -> Sturgeon Electric - Ashlan Ave. Corridor | D2: 119553.54 | E2: 137609
A3: =Revenue!A3 -> 45992 | B3: =Revenue!B3 -> 21.2304 | C3: =Revenue!C3 -> City of Merced - Community Park 42 | D3: 9976795.9 | E3: 9976795.9
A4: =Revenue!A4 -> 45992 | B4: =Revenue!B4 -> 21.231 | C4: =Revenue!C4 -> City of Porterville - Tule River Parkway Phase 3 | D4: 3133296.5 | E4: 3133296.5
A5: =Revenue!A5 -> 45992 | B5: =Revenue!B5 -> 21.2312 | C5: =Revenue!C5 -> City of Fresno - Mariposa Plaza Renovation | D5: 2662730 | E5: 2662730
A6: =Revenue!A6 -> 45992 | B6: =Revenue!B6 -> 21.2314 | C6: =Revenue!C6 -> G.L. Associates Bruno - Clovis VA Parking Expansion | D6: 1184297 | E6: 1184297
A7: =Revenue!A7 -> 45992 | B7: =Revenue!B7 -> 21.2323 | C7: =Revenue!C7 -> WM Lyles - Water Treatment Plant Replacement | D7: 1392857.8 | E7: 1392857.8
A8: =Revenue!A8 -> 45992 | B8: =Revenue!B8 -> 21.2407 | C8: =Revenue!C8 -> City of Fresno - South Peach Park Project | D8: 9282945.1 | E8: 9282945.1
A9: =Revenue!A9 -> 45992 | B9: =Revenue!B9 -> 21.2408 | C9: =Revenue!C9 -> A-C Electric Co. - Friant I.T.S. Phase 2 | D9: 90099.7 | E9: 90099.7
A10: =Revenue!A10 -> 45992 | B10: =Revenue!B10 -> 21.241 | C10: =Revenue!C10 -> City of Fresno - Barstow and Bond Traffic Signal | D10: 1068507 | E10: 1068507
A11: =Revenue!A11 -> 45992 | B11: =Revenue!B11 -> 21.2411 | C11: =Revenue!C11 -> City of Merced - Bob Hart Square Expansion | D11: 3270630.5 | E11: 3270630.5
A12: =Revenue!A12 -> 45992 | B12: =Revenue!B12 -> 21.2412 | C12: =Revenue!C12 -> City of Merced - Main Street Directional (REBID) | D12: 1037873 | E12: 1037873
A13: =Revenue!A13 -> 45992 | B13: =Revenue!B13 -> 21.2502 | C13: =Revenue!C13 -> HPS Mechanical - Well 7 TCP Mitigation Project | D13: 277999.4 | E13: 277999.4
... A45: =Revenue!A45 -> 45992 | B45: =Revenue!B45 -> 20.257 | C45: =Revenue!C45 -> APC Equipment | D45: 28346.72 | E45: 28346.72
