Workbook

Sheet Open Jobs
A1: W.M. Lyles Co.
A2: JOB SUMMARIES BY AREA
A3: FISCAL YEAR ENDING 12/31/25
A4: For the 12 Months Period Ended 12/31/25
M6: Month: | N6: 46022
M8: Anticipated | N8: Contractual | O8: Change in | P8: Previous
A9: Job | B9: Description and | C9: Project | D9: Project | E9: Contract | F9: % | G9: Revenue | H9: Cost | I9: Profit | J9: Prior Year | K9: Current | L9: Revenue | M9: Total | N9: Completion | O9: Anticipated | P9: Anticipated
A10: No. | B10: Customer | C10: Sup | D10: Est | E10: Amount | F10: Comp | G10: to Date | H10: to Date | I10: to Date | J10: Profit | K10: Profit | L10: Remaining | M10: Profit | N10: Date | O10: Profit | P10: Profits | Q10: Notes
A12: Area: | B12: Rocklin
A14: 51.1108 | B14: JV w/AECOM - Stockton - RWCF Phase 2A/2B | C14: DC | D14: Joe, VG, RB, PVT | E14: 94196098 | F14: =H14/(E14-M14) -> 0.99925302 | G14: =H14+I14 -> 94126377 | H14: 93268108 | I14: =IF(F14>0.2,IF(M14>0,IF(J14>M14,M14,IF((F14*M14)>J14,F14*M14,J14)),M14),0) -> 858269 | J14: 858269 | K14: =I14-J14 -> 0 | L14: =E14-G14 -> 69721.29 | M14: 858269 | N14: 46109 | O14: =M14-P14 -> 0 | P14: 858269 | Q14: Through Amendment 23. Includes anticipated profits from the 3% OH generated from the issued JV's SC's & PA's less credit back for management 50hr vs 40hr. Completion date listed for building completion - minus 10% management OH credit back to JV. Adjusted contract value to match anticipated reported on JV financials
A15: 51.1109 | B15: JV w/AECOM - Stockton - RWCF Phase 2A/2B Overhead (JV) | C15: DC | D15: N/A | F15: =H15/(E15-M15) -> 0.98087533 | G15: 0 | H15: -3462489.9 | I15: =G15-H15 -> 3462489.9 | J15: 3470130.8 | K15: =I15-J15 -> -7640.84 | L15: =E15-G15 -> 0 | M15: 3530000 | N15: 46109 | O15: =M15-P15 -> 0 | P15: 3530000 | Q15: Revenue generated by billing to 51.1108.
A16: 51.1129 | B16: Union Sanitary Dist - Enhanced Trtmnt & Site Upgrd Ph. 1A Aeration Basin Modifications | C16: RB/AH | D16: RB/MV | E16: 1.2648358e+08 | F16: =H16/(E16-M16) -> 0.75772321 | G16: =H16+(F16*M16)+534407 -> 96373952 | H16: 87315159 | I16: =G16-H16 -> 9058793.2 | J16: 7950623.4 | K16: =I16-J16 -> 1108169.8 | L16: =E16-G16 -> 30109628 | M16: 11250000 | N16: 46563 | O16: =M16-P16 -> 0 | P16: 11250000 | Q16: Through change order 111 minus 2, 29, 58, 78, 84 & 99. Increase in profits to date are realized buyout items and VE ideas gains. Problem with material delivery delayed the project. Profit projection includes the project realized gains (buyout/VE/profits) and projected losses due to delay.
A17: 51.1137 | B17: CA Water Service Co. - Bear Gulch Pump Station 18 | C17: AH | D17: KS | E17: 1312151.5 | F17: =H17/(E17-M17) -> 0.86960311 | G17: =H17+I17 -> 1141051 | H17: 1042229.3 | I17: =IF(F17>0.2,IF(M17>0,IF(J17>M17,M17,IF((F17*M17)>J17,F17*M17,J17)),M17),0) -> 98821.697 | J17: 27243.589 | K17: =I17-J17 -> 71578.108 | L17: =E17-G17 -> 171100.47 | M17: 113640 | N17: 46053 | O17: =M17-P17 -> 0 | P17: 113640
A18: 51.1144 | B18: Silicon Valley Clean Water - FEP Improvements Project | C18: EL | D18: VG | E18: 14969566 | F18: =H18/(E18-M18) -> 0.60744172 | G18: =H18+I18 -> 9093139 | H18: 8406760.8 | I18: =IF(F18>0.2,IF(M18>0,IF(J18>M18,M18,IF((F18*M18)>J18,F18*M18,J18)),M18),0) -> 686378.17 | J18: 90331.451 | K18: =I18-J18 -> 596046.72 | L18: =E18-G18 -> 5876427 | M18: 1129949 | N18: 46376 | O18: =M18-P18 -> 0 | P18: 1129949 | Q18: Stage 1 Design is to be completed by 9/30/24 by PDB Agreement but is behind -20 days due to Owner Delay. Stage 2 construction anticipated to begin 3/25 and complete by 12/20/26 and is seasonal
A19: 51.1146 | B19: National Carbon Technologies, LLC - Aymium Williams Production Facility | C19: MS | D19: MV | E19: 60980234 | F19: =H19/(E19-M19) -> 0.9294008 | G19: =H19+I19 -> 56675079 | H19: 42734066 | I19: =IF(F19>0.2,IF(M19>0,IF(J19>M19,M19,IF((F19*M19)>J19,F19*M19,J19)),M19),0) -> 13941012 | J19: 510849.94 | K19: =I19-J19 -> 13430162 | L19: =E19-G19 -> 4305155.5 | M19: 15000000 | N19: 46081 | O19: =M19-P19 -> 1400000 | P19: 13600000 | Q19: We demobilized in early November. All in, the Project has the potential to be $20m ($18.2 51.1146 + $1.8 51.1155). This does not include potential greivence settletmens or setttling up with Amyium. Based on all this, the December projection is $15.0m. We are holding back -$1m for Union grievances and another -$2m for other open issues w/ Amyium regarding their refusal to release retention.
A20: 51.1151 | B20: Sonoma Valley County Sanitation Dist. - Sonoma Valley Influent Effluent Upgrade | C20: MV | D20: SS | E20: 10658200 | F20: =H20/(E20-M20) -> 0.48846743 | G20: =H20+I20 -> 5206183.6 | H20: 4923435.2 | I20: =IF(F20>0.2,IF(M20>0,IF(J20>M20,M20,IF((F20*M20)>J20,F20*M20,J20)),M20),0) -> 282748.4 | J20: 0 | K20: =I20-J20 -> 282748.4 | L20: =E20-G20 -> 5452016.4 | M20: 578848 | N20: 46351 | O20: =M20-P20 -> 0 | P20: 578848
A21: 51.1152 | B21: Mozingo Construction Inc - ElD Sly Park Intertie Project | C21: MV | D21: EG | E21: 19974489 | F21: =H21/(E21-M21) -> 0.72332631 | G21: =H21+I21 -> 14448074 | H21: 13474809 | I21: =IF(F21>0.2,IF(M21>0,IF(J21>M21,M21,IF((F21*M21)>J21,F21*M21,J21)),M21),0) -> 973265.21 | J21: 0 | K21: =I21-J21 -> 973265.21 | L21: =E21-G21 -> 5526415.6 | M21: 1345541 | N21: 46203 | O21: =M21-P21 -> 0 | P21: 1345541
A22: 51.1153 | B22: Linda County Water Dist. - Aeration Blower Replacement | C22: JL | D22: JL | E22: 562824.68 | F22: =H22/(E22-M22) -> 0.7360519 | G22: =H22+I22 -> 414268.17 | H22: 334550.81 | I22: =IF(F22>0.2,IF(M22>0,IF(J22>M22,M22,IF((F22*M22)>J22,F22*M22,J22)),M22),0) -> 79717.365 | J22: 12859.389 | K22: =I22-J22 -> 66857.976 | L22: =E22-G22 -> 148556.51 | M22: 108304 | N22: 46053 | O22: =M22-P22 -> 0 | P22: 108304 | Q22: Checking for final invoices, Should move to closed jobs next month
A23: 51.1154 | B23: Keyes Community Services Dist. - TCP Treatment Impvmts Wells 7,8,9,10 | C23: LP | D23: KS | E23: 13363835 | F23: =H23/(E23-M23) -> 0.95063652 | G23: =H23+I23 -> 12704150 | H23: 11872343 | I23: =IF(F23>0.2,IF(M23>0,IF(J23>M23,M23,IF((F23*M23)>J23,F23*M23,J23)),M23),0) -> 831806.95 | J23: 0 | K23: =I23-J23 -> 831806.95 | L23: =E23-G23 -> 659685.45 | M23: 875000 | N23: 46068 | O23: =M23-P23 -> 0 | P23: 875000
A24: 51.1155 | B24: National Carbon Technologies, LLC - Aymium Williams Production Facility - Mgmt Chg Out | F24: =+H24/(E24-M24) -> 1 | G24: =H24+I24 -> 0 | H24: -1783380 | I24: =IF(F24>0,IF(M24>0,IF(J24>M24,M24,IF((F24*M24)>J24,F24*M24,J24)),M24),0) -> 1783380 | J24: 571197.48 | K24: =I24-J24 -> 1212182.5 | L24: =E24-G24 -> 0 | M24: 1783380 | N24: 46081 | O24: =M24-P24 -> -16620.03 | P24: 1800000
A25: 51.1158 | B25: Schneider Electric - City of Ceres WWTP Phase 1- Schneider Electric | E25: 104446 | F25: =+H25/(E25-M25) -> 0.54536019 | G25: =H25+I25 -> 56960.69 | H25: 56960.69 | I25: =IF(F25>0.2,IF(M25>0,IF(J25>M25,M25,IF((F25*M25)>J25,F25*M25,J25)),M25),0) -> 0 | J25: 0 | K25: =I25-J25 -> 0 | L25: =E25-G25 -> 47485.31 | M25: 0 | N25: 46173 | O25: =M25-P25 -> 0 | P25: 0 | Q25: Hold at $0 profit, need to verify final numbers once project path is determined (go/no-go). Do not close WIP.
A26: 51.1159 | B26: El Dorado Irrigation Dist. - EID Reservoir A WTP Backwash-to-waste Valve Repalcement | C26: EG | D26: MV | E26: 1199000 | F26: =+H26/(E26-M26) -> 0.73204396 | G26: =H26+I26 -> 877720.7 | H26: 790051.12 | I26: =IF(F26>0.2,IF(M26>0,IF(J26>M26,M26,IF((F26*M26)>J26,F26*M26,J26)),M26),0) -> 87669.584 | J26: 0 | K26: =I26-J26 -> 87669.584 | L26: =E26-G26 -> 321279.3 | M26: 119760 | N26: 46096 | O26: =M26-P26 -> 0 | P26: 119760
A27: 51.116 | B27: City of Galt Public Works - Industrial WWTP Expansion | C27: JL | D27: MV | E27: 1757000 | F27: =+H27/(E27-M27) -> 0.14823553 | G27: =H27+I27 -> 250518.05 | H27: 250518.05 | I27: =IF(F27>0.2,IF(M27>0,IF(J27>M27,M27,IF((F27*M27)>J27,F27*M27,J27)),M27),0) -> 0 | J27: 0 | K27: =I27-J27 -> 0 | L27: =E27-G27 -> 1506481.9 | M27: 67000 | N27: 46285 | O27: =M27-P27 -> 0 | P27: 67000
A28: 51.1161 | B28: Sacramento Area Sewer Dist. - SASD Influent Pump Nos. 2 and 5 Installation Project | C28: JA | D28: MV | E28: 10848599 | F28: =+H28/(E28-M28) -> 0.058652896 | G28: =H28+I28 -> 601852.17 | H28: 601852.17 | I28: =IF(F28>0.2,IF(M28>0,IF(J28>M28,M28,IF((F28*M28)>J28,F28*M28,J28)),M28),0) -> 0 | J28: 0 | K28: =I28-J28 -> 0 | L28: =E28-G28 -> 10246747 | M28: 587347 | N28: 46366 | O28: =M28-P28 -> 0 | P28: 587347
A29: 51.1162 | B29: City of Chico - Chico Primary Clarifiers No. 1-3 Rehabilitation Project | C29: CT | D29: MV | E29: 6029750 | F29: =+H29/(E29-M29) -> 0.01470274 | G29: =H29+I29 -> 85941.38 | H29: 85941.38 | I29: =IF(F29>0.2,IF(M29>0,IF(J29>M29,M29,IF((F29*M29)>J29,F29*M29,J29)),M29),0) -> 0 | J29: 0 | K29: =I29-J29 -> 0 | L29: =E29-G29 -> 5943808.6 | M29: 184487 | N29: 46681 | O29: =M29-P29 -> 0 | P29: 184487
A30: 51.1164 | B30: CA Water Service Co. - Stockton Roofing | C30: JL | D30: JS | E30: 387260 | F30: =+H30/(E30-M30) -> 0.011380798 | G30: =H30+I30 -> 4363.25 | H30: 4363.25 | I30: =IF(F30>0.2,IF(M30>0,IF(J30>M30,M30,IF((F30*M30)>J30,F30*M30,J30)),M30),0) -> 0 | K30: =I30-J30 -> 0 | L30: =E30-G30 -> 382896.75 | M30: 3873 | N30: 46112 | O30: =M30-P30 -> 3873
A31: 51.1165 | B31: City of Yuba City - WTP Aquifer Storage and Recovery Well No. 3 | C31: EG | D31: MV | E31: 5304500 | F31: =+H31/(E31-M31) -> 0.0047745016 | G31: =H31+I31 -> 23330.33 | H31: 23330.33 | I31: =IF(F31>0.2,IF(M31>0,IF(J31>M31,M31,IF((F31*M31)>J31,F31*M31,J31)),M31),0) -> 0 | K31: =I31-J31 -> 0 | L31: =E31-G31 -> 5281169.7 | M31: 418057 | N31: 46660 | O31: =M31-P31 -> 418057
B33: Rocklin Totals this Month | E33: =SUM(E14:E32) -> 3.6813153e+08 | G33: =SUM(G14:G32) -> 2.9208296e+08 | H33: =SUM(H14:H32) -> 2.5993861e+08 | I33: =SUM(I14:I32) -> 32144351 | J33: =SUM(J14:J32) -> 13491505 | K33: =SUM(K14:K32) -> 18652847 | L33: =SUM(L14:L32) -> 76048576 | M33: =SUM(M14:M32) -> 37953455 | O33: =SUM(O14:O32) -> 1805310 | P33: =SUM(P14:P32) -> 36148145
B34: Rocklin Closed Job Total | E34: ='Closed Jobs'!E23 -> 18225885 | G34: =+'Closed Jobs'!G23 -> 18225885 | H34: =+'Closed Jobs'!H23 -> 18509364 | I34: =+'Closed Jobs'!I23 -> -283479.41 | J34: =+'Closed Jobs'!J23 -> 1459158.3 | K34: =+'Closed Jobs'!K23 -> -1742637.7 | L34: =+'Closed Jobs'!L23 -> 0 | M34: =+'Closed Jobs'!M23 -> -283479.41 | O34: =+'Closed Jobs'!O23 -> -525178.96 | P34: =+'Closed Jobs'!P23 -> 241699.55
B35: Rocklin Total | E35: =E34+E33 -> 3.8635742e+08 | G35: =+G33+G34 -> 3.1030884e+08 | H35: =+H33+H34 -> 2.7844797e+08 | I35: =+I33+I34 -> 31860872 | J35: =+J33+J34 -> 14950663 | K35: =+K33+K34 -> 16910209 | L35: =+L33+L34 -> 76048576 | M35: =+M33+M34 -> 37669976 | O35: =+O33+O34 -> 1280131 | P35: =+P33+P34 -> 36389845
A37: JV | B37: Stockton - RWCF Phase 2A/2B | C37: DC | D37: Joe, VG, RB, PVT | E37: =(225085557/2) -> 1.1254278e+08 | F37: =H37/(E37-M37) -> 0.9990221 | G37: =H37+I37 -> 1.12439e+08 | H37: =((212041638)/2) -> 106020819 | I37: =IF(F37>0.3,IF(M37>0,IF(J37>M37,M37,IF((F37*M37)>J37,F37*M37,J37)),M37),0) -> 6418180.5 | J37: 7118423.5 | K37: =I37-J37 -> -700243 | L37: =E37-G37 -> 103779 | M37: =12836361/2 -> 6418180.5 | N37: 46109 | O37: =M37-P37 -> -31801 | P37: 6449981.5 | Q37: Includes December JV Financials | R37: Profit fade is a result of exceleration of the buildings to complete by Jan '25. Paying for subcontractors to work extended hours and weekends -$250k plus an additional -200k in reimbursable change order work in negotiations with Owner (tracking $400k allowing for 50% recovery). Added another -$100k for future sub accel to complete buildings on time. Overall project impacts on buildings alone due to design/misc. issues - $1.6m. See project narrative for more details.
B39: Rocklin Totals this Month w/ JVs & Closed Jobs | K39: =K37+K35 -> 16209966 | S39: Curr Month | T39: =H35 -> 2.7844797e+08
B40: Rocklin Prior Month Totals w/ JV's & Closed Jobs | K40: 14439549 | S40: Company Activity | T40: -7220844.2
B41: Rocklin Current Month Changes w/ JV's & Closed Jobs | K41: =K39-K40 -> 1770416.5 | T41: =SUM(T39:T40) -> 2.7122713e+08
S43: Prior Month | T43: 2.7122713e+08
A44: Area: | B44: Fresno | S44: Variance | T44: =T41-T43 -> 0
A46: 52.8563 | B46: City of Santa Cruz - Graham Hill WTP Facility Improvements - Phase 1 | C46: RM | D46: JL | E46: 1174182.7 | F46: =+H46/(E46-M46) -> 0.98150165 | G46: =H46+I46 -> 1152462.3 | H46: 1152462.3 | I46: =IF(F46>0.2,IF(M46>0,IF(J46>M46,M46,IF((F46*M46)>J46,F46*M46,J46)),M46),0) -> 0 | J46: 0 | K46: =I46-J46 -> 0 | L46: =E46-G46 -> 21720.44 | M46: 0 | N46: 46059 | O46: =M46-P46 -> 0 | P46: 0
A47: 52.8564 | B47: City of Santa Cruz - Graham Hill WTP Facility Improvements -Mgmt Chg Out | C47: RM | D47: JL | F47: =+H47/(E47-M47) -> 0.99997481 | G47: 0 | H47: -293385.24 | I47: =IF(F47>0.2,IF(M47>0,IF(J47>M47,M47,IF((F47*M47)>J47,F47*M47,J47)),M47),0) -> 293385.24 | J47: 264189.76 | K47: =I47-J47 -> 29195.48 | L47: =E47-G47 -> 0 | M47: 293392.63 | N47: 46059 | O47: =M47-P47 -> 0 | P47: 293392.63 | Q47: Through JV Amendment 4
A48: 52.8566 | B48: City of Visalia - Water Reclamation Facility RPGS SCR System | C48: RM | D48: RM | E48: 1259398 | F48: =+H48/(E48-M48) -> 0.99458232 | G48: =H48+I48 -> 1252575 | H48: 1023821.1 | I48: =IF(F48>0.2,IF(M48>0,IF(J48>M48,M48,IF((F48*M48)>J48,F48*M48,J48)),M48),0) -> 228753.93 | J48: 223974.51 | K48: =I48-J48 -> 4779.4271 | L48: =E48-G48 -> 6823.0166 | M48: 230000 | N48: 46081 | O48: =M48-P48 -> 0 | P48: 230000 | Q48: Waiting on Cummins (owner furnished equipment), to complete their commissioning.
A49: 52.8586 | B49: Tesoro Viejo MMWC- WTP/WWTP/RWSP Phase B Expansion - Phase 1 | C49: RM | D49: RM | E49: 12611349 | F49: =+H49/(E49-M49) -> 0.99100599 | G49: =H49+I49 -> 12497922 | H49: 10565461 | I49: =IF(F49>0.2,IF(M49>0,IF(J49>M49,M49,IF((F49*M49)>J49,F49*M49,J49)),M49),0) -> 1932461.7 | J49: 1757780 | K49: =I49-J49 -> 174681.68 | L49: =E49-G49 -> 113426.58 | M49: 1950000 | N49: 46053 | O49: =M49-P49 -> 0 | P49: 1950000
...

Sheet Closed Jobs
M2: Month: | N2: ='Open Jobs'!N6 -> 46022
M4: Anticipated | O4: Change in | P4: Previous
A5: Job | B5: Customer and | C5: Project | E5: Contract | F5: % | G5: Revenue | H5: Cost | I5: Profit | J5: Prior Year | K5: Current | L5: Revenue | M5: Total | N5: Completion | O5: Anticipated | P5: Anticipated
A6: No. | B6: Description | C6: Sup | D6: Est | E6: Amount | F6: Comp | G6: to Date | H6: to Date | I6: to Date | J6: Profit | K6: Profit | L6: Remaining | M6: Profit | N6: Date | O6: Profit | P6: Profits
A8: Northern Closed Jobs
A10: Area: | B10: Rocklin
A12: 51.1133 | B12: CA Water Service Co. - S. San Francisco St 1-A Pump Replacement | C12: AH | D12: KS | E12: 372738 | F12: =H12/(E12-M12) -> 1 | G12: =H12+I12 -> 372738 | H12: 331855.28 | I12: =IF(F12>0.2,IF(M12>0,IF(J12>M12,M12,IF((F12*M12)>J12,F12*M12,J12)),M12),0) -> 40882.72 | J12: 17359.581 | K12: =I12-J12 -> 23523.139 | L12: =E12-G12 -> 0 | M12: =E12-H12 -> 40882.72 | N12: 45747 | O12: =M12-P12 -> 0 | P12: 40882.72
A13: 51.1136 | B13: Union Sanitary Dist - USD Plant Misc. Improvements | C13: SS | D13: MV | E13: 5483550 | F13: =H13/(E13-M13) -> 1 | G13: =H13+I13 -> 5483550 | H13: 4531817.9 | I13: =IF(F13>0.2,IF(M13>0,IF(J13>M13,M13,IF((F13*M13)>J13,F13*M13,J13)),M13),0) -> 951732.14 | J13: 758905.79 | K13: =I13-J13 -> 192826.35 | L13: =E13-G13 -> 0 | M13: =E13-H13 -> 951732.14 | N13: 46053 | O13: =M13-P13 -> -281873.86 | P13: 1233606
A14: 51.1138 | B14: CA Water Service Co. - Bear Gulch Pump Station 21 | C14: AH | D14: KS | E14: 1120182.1 | F14: =H14/(E14-M14) -> 1 | G14: =H14+I14 -> 1120182.1 | H14: 1167704.1 | I14: =IF(F14>0.2,IF(M14>0,IF(J14>M14,M14,IF((F14*M14)>J14,F14*M14,J14)),M14),0) -> -47522.08 | J14: 77778.099 | K14: =I14-J14 -> -125300.18 | L14: =E14-G14 -> 0 | M14: =E14-H14 -> -47522.08 | N14: 45802 | O14: =M14-P14 -> 0 | P14: -47522.08
A15: 51.1139 | B15: CA Water Service Co. - Bear Gulch Pump Station 14/29 | C15: AH | D15: KS | E15: 61902 | F15: =H15/(E15-M15) -> 1 | G15: =H15+I15 -> 61902 | H15: 56994.44 | I15: =IF(F15>0.2,IF(M15>0,IF(J15>M15,M15,IF((F15*M15)>J15,F15*M15,J15)),M15),0) -> 4907.56 | J15: 4426.359 | K15: =I15-J15 -> 481.20101 | L15: =E15-G15 -> 0 | M15: =E15-H15 -> 4907.56 | N15: 46053 | O15: =M15-P15 -> -5300.17 | P15: 10207.73
A16: 51.1141 | B16: City of Colfax - WWTP Algae Reduction Project | C16: EG | D16: MV | E16: 3967189.8 | F16: =H16/(E16-M16) -> 1 | G16: =H16+I16 -> 3967189.8 | H16: =3846103.91-11009.18 -> 3835094.7 | I16: =IF(F16>0.2,IF(M16>0,IF(J16>M16,M16,IF((F16*M16)>J16,F16*M16,J16)),M16),0) -> 132095.06 | J16: 79920.299 | K16: =I16-J16 -> 52174.761 | L16: =E16-G16 -> 0 | M16: =E16-H16 -> 132095.06 | N16: 45777 | O16: =M16-P16 -> 0 | P16: 132095.06
A17: 51.1143 | B17: Olivehurst Plumas Lake Manganese Filter Expansion | C17: JL | D17: MV | E17: 1991231.4 | F17: =H17/(E17-M17) -> 1 | G17: =H17+I17 -> 1991231.4 | H17: 1758132.6 | I17: =IF(F17>0.2,IF(M17>0,IF(J17>M17,M17,IF((F17*M17)>J17,F17*M17,J17)),M17),0) -> 233098.8 | J17: 226011.76 | K17: =I17-J17 -> 7087.0371 | L17: =E17-G17 -> 0 | M17: =E17-H17 -> 233098.8 | N17: 45833 | O17: =M17-P17 -> 0 | P17: 233098.8
A18: 51.1147 | B18: City of Lodi-Public Works Dept. - Aeration Diffusers Replacement Project | C18: JL | D18: MV | E18: 2742860.1 | F18: =H18/(E18-M18) -> 1 | G18: =H18+I18 -> 2742860.1 | H18: =2547017.95+1595.47+111.5 -> 2548724.9 | I18: =IF(F18>0.2,IF(M18>0,IF(J18>M18,M18,IF((F18*M18)>J18,F18*M18,J18)),M18),0) -> 194135.16 | J18: 128284.54 | K18: =I18-J18 -> 65850.625 | L18: =E18-G18 -> 0 | M18: =E18-H18 -> 194135.16 | N18: 46053 | O18: =M18-P18 -> -111.5 | P18: 194246.66
A19: 51.115 | B19: Sacramento Co. Dept. of Water Resources - D49 Metro Air Park Storm Drain Pump Station Phase 2 | C19: MV | D19: TBD | E19: 2486231.6 | F19: =H19/(E19-M19) -> 1 | G19: =H19+I19 -> 2486231.6 | H19: 2239435.1 | I19: =IF(F19>0.2,IF(M19>0,IF(J19>M19,M19,IF((F19*M19)>J19,F19*M19,J19)),M19),0) -> 246796.44 | J19: 166471.83 | K19: =I19-J19 -> 80324.611 | L19: =E19-G19 -> 0 | M19: =E19-H19 -> 246796.44 | N19: 45747 | O19: =M19-P19 -> 0 | P19: 246796.44
A20: 51.1156 | B20: Rocklin Overhead 2025 | C20: DC | D20: DC | F20: =H20/(E20-M20) -> 1 | G20: =H20+I20 -> 0 | H20: 1426058.7 | I20: =IF(F20>0.2,IF(M20>0,IF(J20>M20,M20,IF((F20*M20)>J20,F20*M20,J20)),M20),0) -> -1426058.7 | J20: 0 | K20: =I20-J20 -> -1426058.7 | L20: =E20-G20 -> 0 | M20: =-H20 -> -1426058.7 | N20: 46022 | O20: =M20-P20 -> -176737.46 | P20: -1249321.2
A21: 51.1157 | B21: Rocklin Estimating 2025 | C21: DC | D21: DC | F21: =H21/(E21-M21) -> 1 | G21: =H21+I21 -> 0 | H21: 613546.52 | I21: =IF(F21>0.2,IF(M21>0,IF(J21>M21,M21,IF((F21*M21)>J21,F21*M21,J21)),M21),0) -> -613546.52 | J21: 0 | K21: =I21-J21 -> -613546.52 | L21: =E21-G21 -> 0 | M21: =-H21 -> -613546.52 | N21: 46022 | O21: =M21-P21 -> -61155.97 | P21: -552390.55
B23: Rocklin Totals this Month | E23: =SUM(E12:E22) -> 18225885 | G23: =SUM(G12:G22) -> 18225885 | H23: =SUM(H12:H22) -> 18509364 | I23: =SUM(I12:I22) -> -283479.41 | J23: =SUM(J12:J22) -> 1459158.3 | K23: =SUM(K12:K22) -> -1742637.7 | L23: =SUM(L12:L22) -> 0 | M23: =SUM(M12:M22) -> -283479.41 | O23: =SUM(O12:O22) -> -525178.96 | P23: =SUM(P12:P22) -> 241699.55
A25: Area: | B25: Fresno
A27: 52.8567 | B27: City of Modesto - Grayson Well 69 | C27: DG | D27: KA | E27: 3059859 | F27: =+H27/(E27-M27) -> 1 | G27: =H27+I27 -> 3059859 | H27: 3128023.9 | I27: =IF(F27>0.2,IF(M27>0,IF(J27>M27,M27,IF((F27*M27)>J27,F27*M27,J27)),M27),0) -> -68164.94 | J27: -83000 | K27: =I27-J27 -> 14835.06 | L27: =E27-G27 -> 0 | M27: =E27-H27 -> -68164.94 | N27: 45807 | O27: =M27-P27 -> 0 | P27: -68164.94
A28: 52.8604 | B28: City of Atwater - Project No. 20-2, Well 20-A TCP Mitigation | C28: TC | D28: GK | E28: 5095691 | F28: =+H28/(E28-M28) -> 1 | G28: =H28+I28 -> 5095691 | H28: =4573089.88-586.65 -> 4572503.2 | I28: =IF(F28>0.2,IF(M28>0,IF(J28>M28,M28,IF((F28*M28)>J28,F28*M28,J28)),M28),0) -> 523187.74 | J28: 329989.13 | K28: =I28-J28 -> 193198.61 | L28: =E28-G28 -> 0 | M28: =E28-H28 -> 523187.74 | N28: 45838 | O28: =M28-P28 -> 0 | P28: 523187.74
A29: 52.8628 | B29: City of Tulare - Well 4-3 Equipping & I Drive Pipeline Proj. | C29: AKC | D29: SF | E29: 5213345.5 | F29: =+H29/(E29-M29) -> 1 | G29: =H29+I29 -> 5213345.5 | H29: 4745798.5 | I29: =IF(F29>0.2,IF(M29>0,IF(J29>M29,M29,IF((F29*M29)>J29,F29*M29,J29)),M29),0) -> 467546.97 | J29: 197224.75 | K29: =I29-J29 -> 270322.22 | L29: =E29-G29 -> 0 | M29: =E29-H29 -> 467546.97 | N29: 46022 | O29: =M29-P29 -> 42546.97 | P29: 425000
A30: 52.8631 | B30: Gunner Ranch, Inc. - Well 1 Equipping and Site Improvements | C30: DG | D30: KA | E30: 2560650.1 | F30: =+H30/(E30-M30) -> 1 | G30: =H30+I30 -> 2560650.1 | H30: 2448658.3 | I30: =IF(F30>0.2,IF(M30>0,IF(J30>M30,M30,IF((F30*M30)>J30,F30*M30,J30)),M30),0) -> 111991.88 | J30: 73003.701 | K30: =I30-J30 -> 38988.179 | L30: =E30-G30 -> 0 | M30: =E30-H30 -> 111991.88 | N30: 46022 | O30: =M30-P30 -> -5008.12 | P30: 117000
A31: 52.8652 | B31: California Water Service Co. - Salinas 77 Booster Station | C31: PR | D31: KA | E31: 1290184 | F31: =+H31/(E31-M31) -> 1 | G31: =H31+I31 -> 1290184 | H31: =1039279.07+97.01 -> 1039376.1 | I31: =IF(F31>0.2,IF(M31>0,IF(J31>M31,M31,IF((F31*M31)>J31,F31*M31,J31)),M31),0) -> 250807.92 | J31: 170698.84 | K31: =I31-J31 -> 80109.083 | L31: =E31-G31 -> 0 | M31: =E31-H31 -> 250807.92 | N31: 45911 | O31: =M31-P31 -> 0 | P31: 250807.92
A32: 52.8658 | B32: California Water Service Co. - Visalia Station 98 Water Storage Tank & Booster Site | C32: MDA | D32: SF | E32: 1870915 | F32: =+H32/(E32-M32) -> 1 | G32: =H32+I32 -> 1870915 | H32: 1633530.2 | I32: =IF(F32>0.2,IF(M32>0,IF(J32>M32,M32,IF((F32*M32)>J32,F32*M32,J32)),M32),0) -> 237384.78 | J32: 148751 | K32: =I32-J32 -> 88633.78 | L32: =E32-G32 -> 0 | M32: =E32-H32 -> 237384.78 | N32: 45868 | O32: =M32-P32 -> 0 | P32: 237384.78
A33: 52.8663 | B33: Root Creek Water Dist. - Ag Well 277 Conversion Project | C33: LP | D33: RM | E33: 1641800 | F33: =+H33/(E33-M33) -> 1 | G33: =H33+I33 -> 1641800 | H33: 1379688.3 | I33: =IF(F33>0.2,IF(M33>0,IF(J33>M33,M33,IF((F33*M33)>J33,F33*M33,J33)),M33),0) -> 262111.72 | J33: 42676.951 | K33: =I33-J33 -> 219434.77 | L33: =E33-G33 -> 0 | M33: =E33-H33 -> 262111.72 | N33: 46081 | O33: =M33-P33 -> 2111.72 | P33: 260000
A34: 52.8667 | B34: California Water Service Co. - Cal Water Salinas Station 33 | C34: EB | D34: KA | E34: 314085.77 | F34: =+H34/(E34-M34) -> 1 | G34: =H34+I34 -> 314085.77 | H34: 290726.11 | I34: =IF(F34>0.3,IF(M34>0,IF(J34>M34,M34,IF((F34*M34)>J34,F34*M34,J34)),M34),0) -> 23359.66 | J34: 26868.865 | K34: =I34-J34 -> -3509.2053 | L34: =E34-G34 -> 0 | M34: =E34-H34 -> 23359.66 | N34: 45808 | O34: =M34-P34 -> 0 | P34: 23359.66
A35: 52.867 | B35: California Water Service Co. - Cal Water - King City Station 10 | C35: EB | D35: SF | E35: 274166.01 | F35: =+H35/(E35-M35) -> 1 | G35: =H35+I35 -> 274166.01 | H35: 267282.05 | I35: =IF(F35>0.3,IF(M35>0,IF(J35>M35,M35,IF((F35*M35)>J35,F35*M35,J35)),M35),0) -> 6883.96 | J35: 10404.436 | K35: =I35-J35 -> -3520.4756 | L35: =E35-G35 -> 0 | M35: =E35-H35 -> 6883.96 | N35: 45838 | O35: =M35-P35 -> 0 | P35: 6883.96
A36: 52.8674 | B36: City of Hanford - WWTP Standby Influent Pump Install | C36: DG | D36: SF | E36: 279244 | F36: =+H36/(E36-M36) -> 1 | G36: =H36+I36 -> 279244 | H36: 251088.2 | I36: =IF(F36>0.2,IF(M36>0,IF(J36>M36,M36,IF((F36*M36)>J36,F36*M36,J36)),M36),0) -> 28155.8 | J36: 15534.584 | K36: =I36-J36 -> 12621.216 | L36: =E36-G36 -> 0 | M36: =E36-H36 -> 28155.8 | N36: 45688 | O36: =M36-P36 -> 0 | P36: 28155.8
A37: 52.8677 | B37: Gunner Ranch, Inc. - CSA 22C Tank and PW2 Site Improvements | C37: DG | D37: SF | E37: 796055.3 | F37: =+H37/(E37-M37) -> 1 | G37: =H37+I37 -> 796055.3 | H37: 689831.96 | I37: =IF(F37>0.2,IF(M37>0,IF(J37>M37,M37,IF((F37*M37)>J37,F37*M37,J37)),M37),0) -> 106223.34 | J37: 0 | K37: =I37-J37 -> 106223.34 | L37: =E37-G37 -> 0 | M37: =E37-H37 -> 106223.34 | N37: 46022 | O37: =M37-P37 -> 18223.34 | P37: 88000
A38: 52.868 | B38: City of Orange Cove - Orange Cove West Clarifier T&M | C38: DG | D38: DG | E38: 29838.25 | F38: =+H38/(E38-M38) -> 1 | G38: =H38+I38 -> 29838.25 | H38: 26088.33 | I38: =IF(F38>0.2,IF(M38>0,IF(J38>M38,M38,IF((F38*M38)>J38,F38*M38,J38)),M38),0) -> 3749.92 | J38: 0 | K38: =I38-J38 -> 3749.92 | L38: =E38-G38 -> 0 | M38: =E38-H38 -> 3749.92 | N38: 45838 | O38: =M38-P38 -> 0 | P38: 3749.92
A39: 52.8682 | B39: Fresno Overhead 2025 | C39: RM | D39: RM | F39: =+H39/(E39-M39) -> 1 | G39: =H39+I39 -> 0 | H39: 1121157.1 | I39: =IF(F39>0.2,IF(M39>0,IF(J39>M39,M39,IF((F39*M39)>J39,F39*M39,J39)),M39),0) -> -1121157.1 | J39: 0 | K39: =I39-J39 -> -1121157.1 | L39: =E39-G39 -> 0 | M39: =-H39 -> -1121157.1 | N39: 46022 | O39: =M39-P39 -> -156002.73 | P39: -965154.37
A40: 52.8683 | B40: Fresno Estimating 2025 | C40: RM | D40: RM | F40: =+H40/(E40-M40) -> 1 | G40: =H40+I40 -> 0 | H40: 415452.52 | I40: =IF(F40>0.2,IF(M40>0,IF(J40>M40,M40,IF((F40*M40)>J40,F40*M40,J40)),M40),0) -> -415452.52 | J40: 0 | K40: =I40-J40 -> -415452.52 | L40: =E40-G40 -> 0 | M40: =-H40 -> -415452.52 | N40: 46022 | O40: =M40-P40 -> -64541.14 | P40: -350911.38
A41: 52.8684 | B41: Lakeside Ditch Co. - Lakeland Radial Gate Repair (T&M) | C41: JL | D41: JL | E41: 50568.05 | F41: =+H41/(E41-M41) -> 1 | G41: =H41+I41 -> 50568.05 | H41: =45194.09+97.3 -> 45291.39 | I41: =IF(F41>0.2,IF(M41>0,IF(J41>M41,M41,IF((F41*M41)>J41,F41*M41,J41)),M41),0) -> 5276.66 | J41: 0 | K41: =I41-J41 -> 5276.66 | L41: =E41-G41 -> 0 | M41: =E41-H41 -> 5276.66 | N41: 45939 | O41: =M41-P41 -> 830.03 | P41: 4446.63
A42: 52.8685 | B42: Malaga County Water Dist. - Malaga County Water District | C42: DG | D42: JS | E42: 451254 | F42: =+H42/(E42-M42) -> 1 | G42: =H42+I42 -> 451254 | H42: 382067.32 | I42: =IF(F42>0.2,IF(M42>0,IF(J42>M42,M42,IF((F42*M42)>J42,F42*M42,J42)),M42),0) -> 69186.68 | J42: 0 | K42: =I42-J42 -> 69186.68 | L42: =E42-G42 -> 0 | M42: =E42-H42 -> 69186.68 | N42: 46022 | O42: =M42-P42 -> 34186.68 | P42: 35000
A43: 52.8686 | B43: Root Creek Water Dist. - Groundwater - 48-Inch RCP Repair | C43: LP | D43: LP | E43: 23957 | F43: =+H43/(E43-M43) -> 1 | G43: =H43+I43 -> 23957 | H43: =7389.72+115.54 -> 7505.26 | I43: =IF(F43>0.2,IF(M43>0,IF(J43>M43,M43,IF((F43*M43)>J43,F43*M43,J43)),M43),0) -> 16451.74 | J43: 15372.257 | K43: =I43-J43 -> 1079.4833 | L43: =E43-G43 -> 0 | M43: =E43-H43 -> 16451.74 | N43: 46022 | O43: =M43-P43 -> 0 | P43: 16451.74
A44: 52.8688 | B44: New England Sheet Metal and Mechanical Co. - Valley Children's Hospital NESM Trench Limits | C44: DG | D44: DG | E44: 132492.2 | F44: =+H44/(E44-M44) -> 1 | G44: =H44+I44 -> 132492.2 | H44: 116972.75 | I44: =IF(F44>0.2,IF(M44>0,IF(J44>M44,M44,IF((F44*M44)>J44,F44*M44,J44)),M44),0) -> 15519.45 | J44: 0 | K44: =I44-J44 -> 15519.45 | L44: =E44-G44 -> 0 | M44: =E44-H44 -> 15519.45 | N44: 45900 | O44: =M44-P44 -> 0 | P44: 15519.45
A45: 52.8689 | B45: City of Sanger - Public Works Dept. - City of Sanger WWTP- Remove and Install Valves T&M | C45: DG | D45: DG | E45: 16665.83 | F45: =+H45/(E45-M45) -> 1 | G45: =H45+I45 -> 16665.83 | H45: 16095.58 | I45: =IF(F45>0.2,IF(M45>0,IF(J45>M45,M45,IF((F45*M45)>J45,F45*M45,J45)),M45),0) -> 570.25 | K45: =I45-J45 -> 570.25 | L45: =E45-G45 -> 0 | M45: =E45-H45 -> 570.25 | N45: 45808 | O45: =M45-P45 -> 0 | P45: 570.25
A46: 52.869 | B46: City of Dinuba - WWTP Rake Replacement | C46: DG | D46: DG | E46: 14151.97 | F46: =+H46/(E46-M46) -> 1 | G46: =H46+I46 -> 14151.97 | H46: 13155.83 | I46: =IF(F46>0.2,IF(M46>0,IF(J46>M46,M46,IF((F46*M46)>J46,F46*M46,J46)),M46),0) -> 996.14 | K46: =I46-J46 -> 996.14 | L46: =E46-G46 -> 0 | M46: =E46-H46 -> 996.14 | N46: 45779 | O46: =M46-P46 -> 0 | P46: 996.14
A47: 52.8691 | B47: County of Fresno - Quail Lakes Repair at Bodega Bay Rd | C47: TC | D47: TC | E47: 11302.84 | F47: =+H47/(E47-M47) -> 1 | G47: =H47+I47 -> 11302.84 | H47: 8287.82 | I47: =IF(F47>0.2,IF(M47>0,IF(J47>M47,M47,IF((F47*M47)>J47,F47*M47,J47)),M47),0) -> 3015.02 | J47: 0 | K47: =I47-J47 -> 3015.02 | L47: =E47-G47 -> 0 | M47: =E47-H47 -> 3015.02 | N47: 45838 | O47: =M47-P47 -> 0 | P47: 3015.02
A48: 52.8693 | B48: New England Sheet Metal and Mechanical Co. - VCH Service Meter Connections | C48: AC | D48: RH | E48: 1120704.2 | F48: =+H48/(E48-M48) -> 1 | G48: =H48+I48 -> 1120704.2 | H48: 663140.99 | I48: =IF(F48>0.2,IF(M48>0,IF(J48>M48,M48,IF((F48*M48)>J48,F48*M48,J48)),M48),0) -> 457563.21 | J48: 0 | K48: =I48-J48 -> 457563.21 | L48: =E48-G48 -> 0 | M48: =E48-H48 -> 457563.21 | N48: 46022 | O48: =M48-P48 -> 27563.21 | P48: 430000
...
