Workbook

Sheet JV GAAP WIP
A1: W.M. Lyles Co.
A2: JV WORK IN PROCESS-GAAP BASIS
A3: ='JV GAAP'!A4 -> For the 12 Months Period Ended 12/31/25
C5: AMOUNT | D5: REMAINING | E5: TOTAL | F5: COSTS | G5: ESTIMATED | H5: TOTAL | I5: TOTAL | J5: % OF | L5: OVER
C6: BILLED | D6: TO BE | E6: ESTIMATED | F6: INCURED | G6: COSTS TO | H6: ESTIMATED | I6: ESTIMATED | J6: COMPLETION | K6: PROFIT / | L6: (UNDER)
A7: AREA | B7: DESCRIPTION | C7: TO DATE | D7: BILLED | E7: CONTRACT | F7: TO DATE | G7: COMPLETE | H7: COSTS | I7: PROFIT | J7: COST/COST | K7: LOSS | L7: BILLIING
A9: ='JV GAAP'!A11 -> Northern | B9: ='JV GAAP'!B11 -> Stockton Phase 1 | C9: ='JV GAAP'!K11 -> 5508112 | D9: ='JV GAAP'!N11 -> 0 | E9: ='JV GAAP'!D11 -> 5508112 | F9: ='JV GAAP'!G11 -> 4939022 | G9: ='JV GAAP'!M11 -> 0 | H9: ='JV GAAP'!E11 -> 4939022 | I9: ='JV GAAP'!F11 -> 569090 | J9: ='JV GAAP'!H11 -> 1 | K9: ='JV GAAP'!I11 -> 569090 | L9: ='JV GAAP'!L11 -> 0
A10: ='JV GAAP'!A12 -> Northern | B10: ='JV GAAP'!B12 -> Stockton Phase 2 | C10: ='JV GAAP'!K12 -> 225085557 | D10: ='JV GAAP'!N12 -> 644014.63 | E10: ='JV GAAP'!D12 -> 2.2572957e+08 | F10: ='JV GAAP'!G12 -> 2.12615e+08 | G10: ='JV GAAP'!M12 -> 0 | H10: ='JV GAAP'!E12 -> 2.12615e+08 | I10: ='JV GAAP'!F12 -> 13114570 | J10: ='JV GAAP'!H12 -> 1 | K10: ='JV GAAP'!I12 -> 13114570 | L10: ='JV GAAP'!L12 -> -644014.63
A11: ='JV GAAP'!A13 -> Northern | B11: ='JV GAAP'!B13 -> City of Santa Cruz - Graham Hill WTP | C11: ='JV GAAP'!K13 -> 11042468 | D11: ='JV GAAP'!N13 -> 55906.69 | E11: ='JV GAAP'!D13 -> 11098374 | F11: ='JV GAAP'!G13 -> 10929118 | G11: ='JV GAAP'!M13 -> 0 | H11: ='JV GAAP'!E13 -> 10929118 | I11: ='JV GAAP'!F13 -> 169256.76 | J11: ='JV GAAP'!H13 -> 1 | K11: ='JV GAAP'!I13 -> 169256.76 | L11: ='JV GAAP'!L13 -> -55906.69
A12: ='JV GAAP'!A14 -> Southern | B12: ='JV GAAP'!B14 -> Silverlake | C12: ='JV GAAP'!K14 -> 364279554 | D12: ='JV GAAP'!N14 -> 2066292 | E12: ='JV GAAP'!D14 -> 366345846 | F12: ='JV GAAP'!G14 -> 3.3529479e+08 | G12: ='JV GAAP'!M14 -> 5666024.4 | H12: ='JV GAAP'!E14 -> 340960819 | I12: ='JV GAAP'!F14 -> 25385027 | J12: ='JV GAAP'!H14 -> 0.98338218 | K12: ='JV GAAP'!I14 -> 25406592 | L12: ='JV GAAP'!L14 -> 3578167
A13: ='JV GAAP'!A15 -> Southern | B13: ='JV GAAP'!B15 -> East County Advanced Package 1 | C13: ='JV GAAP'!K15 -> 4.1684452e+08 | D13: ='JV GAAP'!N15 -> 63585781 | E13: ='JV GAAP'!D15 -> 4.804303e+08 | F13: ='JV GAAP'!G15 -> 4.0411575e+08 | G13: ='JV GAAP'!M15 -> 48017632 | H13: ='JV GAAP'!E15 -> 4.5213338e+08 | I13: ='JV GAAP'!F15 -> 28296915 | J13: ='JV GAAP'!H15 -> 0.89379764 | K13: ='JV GAAP'!I15 -> 30680783 | L13: ='JV GAAP'!L15 -> -17952016
A14: ='JV GAAP'!A16 -> Southern | B14: ='JV GAAP'!B16 -> East County Advanced Package 3 | C14: ='JV GAAP'!K16 -> 73088486 | D14: ='JV GAAP'!N16 -> 21497344 | E14: ='JV GAAP'!D16 -> 94585830 | F14: ='JV GAAP'!G16 -> 92385154 | G14: ='JV GAAP'!M16 -> 0 | H14: ='JV GAAP'!E16 -> 92385154 | I14: ='JV GAAP'!F16 -> 2200676.8 | J14: ='JV GAAP'!H16 -> 1 | K14: ='JV GAAP'!I16 -> 2200676.8 | L14: ='JV GAAP'!L16 -> -21497344
A15: ='JV GAAP'!A17 -> Southern | B15: ='JV GAAP'!B17 -> City of Banning | C15: ='JV GAAP'!K17 -> 1255755.8 | D15: ='JV GAAP'!N17 -> 2742872.2 | E15: ='JV GAAP'!D17 -> 3998628 | F15: ='JV GAAP'!G17 -> 1142481.3 | G15: ='JV GAAP'!M17 -> 2492634.7 | H15: ='JV GAAP'!E17 -> 3635116 | I15: ='JV GAAP'!F17 -> 363512 | J15: ='JV GAAP'!H17 -> 0.31429019 | K15: ='JV GAAP'!I17 -> 113274.33 | L15: ='JV GAAP'!L17 -> 0.13
C17: =SUM(C9:C16) -> 1.0971044e+09 | D17: =SUM(D9:D16) -> 90592211 | E17: =SUM(E9:E16) -> 1.1876967e+09 | F17: =SUM(F9:F16) -> 1.0614213e+09 | G17: =SUM(G9:G16) -> 56176292 | H17: =SUM(H9:H16) -> 1.1175976e+09 | I17: =SUM(I9:I16) -> 70099047 | K17: =SUM(K9:K16) -> 72254243 | L17: =SUM(L9:L16) -> -36571115

Sheet JV GAAP
A1: W.M. Lyles Co.
A2: JV WORK IN PROCESS
A3: FISCAL YEAR ENDING 12/31/25
A4: For the 12 Months Period Ended 12/31/25
A7: Full JV
D8: CONTRACT | E8: EST. TOTAL | F8: EXPECTED | G8: JOB TO DATE | H8: COST / | I8: JOB TO DATE | J8: JOB TO DATE | M8: EST. COST TO | N8: CONTRACT | O8: PRIOR YR | P8: CURRENT
A9: AREA | B9: DESCRIPTION | D9: AMOUNT | E9: COSTS | F9: PROFIT | G9: JOB COSTS | H9: COST | I9: PROFIT/LOSS | J9: EARNED REV. | K9: JTD BILLED | L9: CURRENT WIP | M9: COMPLETE | N9: BALANCE | O9: JTD PROFIT | P9: YTD PROFIT
A10: JV Projects
A11: Northern | B11: Stockton Phase 1 | D11: 5508112 | E11: =D11-F11 -> 4939022 | F11: 569090 | G11: 4939022 | H11: =IF(E11<>0,+G11/E11,0) -> 1 | I11: 569090 | J11: =+G11+I11 -> 5508112 | K11: 5508112 | L11: =K11-J11 -> 0 | M11: =+E11-G11 -> 0 | N11: =+D11-K11 -> 0 | O11: =O26*2 -> 569090 | P11: =I11-O11 -> 0
A12: Northern | B12: Stockton Phase 2 | D12: 2.2572957e+08 | E12: 2.12615e+08 | F12: =D12-E12 -> 13114570 | G12: 2.12615e+08 | H12: =IF(E12<>0,+G12/E12,0) -> 1 | I12: =J12-G12 -> 13114570 | J12: 2.2572957e+08 | K12: 225085557 | L12: =K12-J12 -> -644014.63 | M12: =+E12-G12 -> 0 | N12: =+D12-K12 -> 644014.63 | O12: =O27*2 -> 19477451 | P12: =I12-O12 -> -6362880.5
A13: Northern | B13: City of Santa Cruz - Graham Hill WTP | D13: 11098374 | E13: 10929118 | F13: =D13-E13 -> 169256.76 | G13: 10929118 | H13: =IF(E13<>0,+G13/E13,0) -> 1 | I13: =J13-G13 -> 169256.76 | J13: 11098374 | K13: 11042468 | L13: =K13-J13 -> -55906.69 | M13: =+E13-G13 -> 0 | N13: =+D13-K13 -> 55906.69 | O13: =O28*2 -> -62367.34 | P13: =I13-O13 -> 231624.1
A14: Southern | B14: Silverlake | D14: 366345846 | E14: =D14-F14 -> 340960819 | F14: 25385027 | G14: =G29*4 -> 3.3529479e+08 | H14: =IF(E14<>0,+G14/E14,0) -> 0.98338218 | I14: =I29*4 -> 25406592 | J14: =+G14+I14 -> 360701387 | K14: 364279554 | L14: =K14-J14 -> 3578167 | M14: =+E14-G14 -> 5666024.4 | N14: =+D14-K14 -> 2066292 | O14: =O29/0.25 -> 24716046 | P14: =I14-O14 -> 690546
A15: Southern | B15: East County Advanced Package 1 | D15: 4.804303e+08 | E15: =D15-F15 -> 4.5213338e+08 | F15: 28296915 | G15: 4.0411575e+08 | H15: =IF(E15<>0,+G15/E15,0) -> 0.89379764 | I15: 30680783 | J15: =+G15+I15 -> 4.3479653e+08 | K15: 4.1684452e+08 | L15: =K15-J15 -> -17952016 | M15: =+E15-G15 -> 48017632 | N15: =+D15-K15 -> 63585781 | O15: =O30*2 -> 26187673 | P15: =I15-O15 -> 4493110
A16: Southern | B16: East County Advanced Package 3 | D16: 94585830 | E16: 92385154 | F16: =D16-E16 -> 2200676.8 | G16: 92385154 | H16: =IF(E16<>0,+G16/E16,0) -> 1 | I16: =J16-G16 -> 2200676.8 | J16: 94585830 | K16: 73088486 | L16: =K16-J16 -> -21497344 | M16: =+E16-G16 -> 0 | N16: =+D16-K16 -> 21497344 | O16: =O31*2 -> 3468742.3 | P16: =I16-O16 -> -1268065.5
A17: Southern | B17: City of Banning | D17: 3998628 | E17: =D17-F17 -> 3635116 | F17: 363512 | G17: 1142481.3 | H17: =IF(E17<>0,+G17/E17,0) -> 0.31429019 | I17: 113274.33 | J17: =+G17+I17 -> 1255755.6 | K17: 1255755.8 | L17: =K17-J17 -> 0.13 | M17: =+E17-G17 -> 2492634.7 | N17: =+D17-K17 -> 2742872.2 | O17: =O32*2 -> 0 | P17: =I17-O17 -> 113274.33
A19: Grand Totals | D19: =SUM(D11:D18) -> 1.1876967e+09 | E19: =SUM(E11:E18) -> 1.1175976e+09 | F19: =SUM(F11:F18) -> 70099047 | G19: =SUM(G11:G18) -> 1.0614213e+09 | I19: =SUM(I11:I18) -> 72254243 | J19: =SUM(J11:J18) -> 1.1336756e+09 | K19: =SUM(K11:K18) -> 1.0971044e+09 | L19: =SUM(L11:L18) -> -36571115 | M19: =SUM(M11:M18) -> 56176292 | N19: =SUM(N11:N18) -> 90592211 | O19: =SUM(O11:O18) -> 74356635 | P19: =SUM(P11:P18) -> -2102391.6
A22: WML Portion
A24: AREA | B24: DESCRIPTION | C24: % of JV | D24: CONTRACT AMOUNT | E24: EST. TOTALS COSTS | F24: EXPECTED PROFIT | G24: JOB TO DATE JOB COSTS | H24: COST/COST | I24: JOB TO DATE PROFIT/LOSS | J24: JOB TO DATE EARNED REV. | K24: JTD BILLED | L24: CURRENT WIP | M24: EST. COST TO COMPLETE | N24: CONTRACT BALANCE | O24: PRIOR YR JTD PROFIT | P24: CURRENT YTD PROFIT
A25: JV Projects
A26: Northern | B26: Stockton Phase 1 | C26: 0.5 | D26: =D11/2 -> 2754056 | E26: =D26-F26 -> 2469511 | F26: =F11/2 -> 284545 | G26: =G11/2 -> 2469511 | H26: =IF(E26<>0,+G26/E26,0) -> 1 | I26: =I11/2 -> 284545 | J26: =+G26+I26 -> 2754056 | K26: =K11/2 -> 2754056 | L26: =K26-J26 -> 0 | M26: =+E26-G26 -> 0 | N26: =+D26-K26 -> 0 | O26: 284545 | P26: =I26-O26 -> 0
A27: Northern | B27: Stockton Phase 2 | C27: 0.5 | D27: =D12/2 -> 1.1286479e+08 | E27: =D27-F27 -> 1.063075e+08 | F27: =F12/2 -> 6557285 | G27: =G12/2 -> 1.063075e+08 | H27: =IF(E27<>0,+G27/E27,0) -> 1 | I27: =I12/2 -> 6557285 | J27: =+G27+I27 -> 1.1286479e+08 | K27: =K12/2 -> 1.1254278e+08 | L27: =K27-J27 -> -322007.31 | M27: =+E27-G27 -> 0 | N27: =+D27-K27 -> 322007.31 | O27: 9738725.3 | P27: =I27-O27 -> -3181440.3
A28: Northern | B28: City of Santa Cruz - Graham Hill WTP | C28: 0.5 | D28: =D13/2 -> 5549187.2 | E28: =D28-F28 -> 5464558.9 | F28: =F13/2 -> 84628.38 | G28: =G13/2 -> 5464558.9 | H28: =IF(E28<>0,+G28/E28,0) -> 1 | I28: =I13/2 -> 84628.38 | J28: =+G28+I28 -> 5549187.2 | K28: =K13/2 -> 5521233.9 | L28: =K28-J28 -> -27953.345 | M28: =+E28-G28 -> 0 | N28: =+D28-K28 -> 27953.345 | O28: -31183.67 | P28: =I28-O28 -> 115812.05
A29: Southern | B29: Silverlake | C29: 0.25 | D29: =D14*0.25 -> 91586462 | E29: =D29-F29 -> 85240205 | F29: =F14*0.25 -> 6346256.8 | G29: 83823699 | H29: =IF(E29<>0,+G29/E29,0) -> 0.98338218 | I29: 6351648.1 | J29: =+G29+I29 -> 90175347 | K29: =K14*0.25 -> 91069888 | L29: =K29-J29 -> 894541.75 | M29: =+E29-G29 -> 1416506.1 | N29: =+D29-K29 -> 516573 | O29: 6179011.6 | P29: =I29-O29 -> 172636.5
A30: Southern | B30: East County Advanced Package 1 | C30: 0.5 | D30: =D15/2 -> 2.4021515e+08 | E30: =D30-F30 -> 2.2606669e+08 | F30: =F15/2 -> 14148457 | G30: =G15/2 -> 2.0205787e+08 | H30: =IF(E30<>0,+G30/E30,0) -> 0.89379764 | I30: =I15/2 -> 15340391 | J30: =+G30+I30 -> 2.1739827e+08 | K30: =K15/2 -> 2.0842226e+08 | L30: =K30-J30 -> -8976008.1 | M30: =+E30-G30 -> 24008816 | N30: =+D30-K30 -> 31792890 | O30: 13093836 | P30: =I30-O30 -> 2246555
A31: Southern | B31: East County Advanced Package 3 | C31: 0.5 | D31: =D16/2 -> 47292915 | E31: =D31-F31 -> 46192577 | F31: =F16/2 -> 1100338.4 | G31: =G16/2 -> 46192577 | H31: =IF(E31<>0,+G31/E31,0) -> 1 | I31: =I16/2 -> 1100338.4 | J31: =+G31+I31 -> 47292915 | K31: =K16/2 -> 36544243 | L31: =K31-J31 -> -10748672 | M31: =+E31-G31 -> 0 | N31: =+D31-K31 -> 10748672 | O31: 1734371.1 | P31: =I31-O31 -> -634032.74
A32: Southern | B32: City of Banning | C32: 0.5 | D32: =D17/2 -> 1999314 | E32: =D32-F32 -> 1817558 | F32: =F17/2 -> 181756 | G32: =G17/2 -> 571240.65 | H32: =IF(E32<>0,+G32/E32,0) -> 0.31429019 | I32: =I17/2 -> 56637.165 | J32: =+G32+I32 -> 627877.82 | K32: =K17/2 -> 627877.88 | L32: =K32-J32 -> 0.065 | M32: =+E32-G32 -> 1246317.4 | N32: =+D32-K32 -> 1371436.1 | O32: 0 | P32: =I32-O32 -> 56637.165
A34: Totals | D34: =SUM(D26:D33) -> 5.0226187e+08 | E34: =SUM(E26:E33) -> 4.735586e+08 | F34: =SUM(F26:F33) -> 28703267 | G34: =SUM(G26:G33) -> 4.4688696e+08 | I34: =SUM(I26:I33) -> 29775474 | J34: =SUM(J26:J33) -> 4.7666243e+08 | K34: =SUM(K26:K33) -> 4.5748234e+08 | L34: =SUM(L26:L33) -> -19180099 | M34: =SUM(M26:M33) -> 26671640 | N34: =SUM(N26:N33) -> 44779532 | O34: =SUM(O26:O33) -> 30999306 | P34: =SUM(P26:P33) -> -1223832.3
A37: JTD Profit Comparison
D38: GAAP | E38: BONUS
A39: AREA | B39: Description | D39: PROFIT | E39: PROFIT | F39: Variance
A40: JV Projects
A41: Northern | B41: Stockton Phase 1 | D41: =I26 -> 284545 | E41: 284545 | F41: =D41-E41 -> 0
A42: Northern | B42: Stockton Phase 2 | D42: =I27 -> 6557285 | E42: 6418180.5 | F42: =D42-E42 -> 139104.5
A43: Northern | B43: City of Santa Cruz - Graham Hill WTP | D43: =I28 -> 84628.38 | E43: 17162.5 | F43: =D43-E43 -> 67465.88
A44: Southern | B44: Silverlake | D44: =I29 -> 6351648.1 | E44: 6242676.8 | F44: =D44-E44 -> 108971.36
A45: Southern | B45: East County Advanced Package 1 | D45: =I30 -> 15340391 | E45: 8546652 | F45: =D45-E45 -> 6793739.4
A46: Southern | B46: East County Advanced Package 3 | D46: =I31 -> 1100338.4 | E46: -10262956 | F46: =D46-E46 -> 11363294
A47: Southern | B47: City of Banning | D47: =I32 -> 56637.165 | E47: 0 | F47: =D47-E47 -> 56637.165
A49: WML % JV Job Totals | D49: =SUM(D41:D48) -> 29775474 | E49: =SUM(E41:E48) -> 11246261 | F49: =SUM(F41:F48) -> 18529213

Sheet Bonus vs GAAP
A1: W. M. Lyles Co.
A2: Bonus vs. GAAP Comparison
A3: =GAAP!A4 -> For the Month Period Ended 12/31/2025
E5: Job to Date | Q5: Year to Date | AC5: 2024 Job to Date
C6: Bonus | D6: GAAP | E6: Bonus | I6: GAAP | M6: Bonus vs GAAP | Q6: Bonus | U6: GAAP | Y6: Bonus vs GAAP
A7: Job | B7: Description | C7: % Complete | D7: % Complete | E7: Revenue | F7: Cost | G7: Profit | I7: Revenue | J7: Cost | K7: Profit | M7: Revenue | N7: Cost | O7: Profit | Q7: Revenue | R7: Cost | S7: Profit | U7: Revenue | V7: Cost | W7: Profit | Y7: Revenue | Z7: Cost | AA7: Profit | AC7: Bonus vs GAAP
A8: Rocklin Open Jobs | AC8: =O8-AA8 -> 0
A9: =Bonus!A9 -> 51.1108 | B9: =Bonus!B9 -> City of Stockton - RWCF Phase 2A/2B | C9: =Bonus!G9 -> 0.99997538 | D9: =GAAP!G9 -> 1 | E9: =Bonus!I9 -> 94126377 | F9: =Bonus!F9 -> 89805618 | G9: =E9-F9 -> 4320758.9 | I9: =GAAP!I9 -> 94045648 | J9: =GAAP!F9 -> 89805618 | K9: =I9-J9 -> 4240030.1 | M9: =E9-I9 -> 80728.85 | N9: =F9-J9 -> 0 | O9: =G9-K9 -> 80728.85 | Q9: =R9+S9 -> 1278782 | R9: =Bonus!Q9 -> 1286422.8 | S9: =Bonus!S9 -> -7640.84 | U9: =V9+W9 -> 1490690.3 | V9: =GAAP!Q9 -> 1286422.8 | W9: =GAAP!S9 -> 204267.49 | Y9: =Q9-U9 -> -211908.33 | Z9: =R9-V9 -> 0 | AA9: =S9-W9 -> -211908.33 | AC9: =O9-AA9 -> 292637.18
A10: =Bonus!A10 -> 51.1129 | B10: =Bonus!B10 -> Union Sanit. Dist - Enhanced Trtmnt & Site Upgrd Ph. 1A Aeration Basin | C10: =Bonus!G10 -> 0.75772321 | D10: =GAAP!G10 -> 0.75772321 | E10: =Bonus!I10 -> 96373952 | F10: =Bonus!F10 -> 87315159 | G10: =E10-F10 -> 9058793.2 | I10: =GAAP!I10 -> 95839545 | J10: =GAAP!F10 -> 87315159 | K10: =I10-J10 -> 8524386.2 | M10: =E10-I10 -> 534407 | N10: =F10-J10 -> 0 | O10: =G10-K10 -> 534407 | Q10: =R10+S10 -> 24666258 | R10: =Bonus!Q10 -> 23558089 | S10: =Bonus!S10 -> 1108169.8 | U10: =V10+W10 -> 25124997 | V10: =GAAP!Q10 -> 23558089 | W10: =GAAP!S10 -> 1566908.8 | Y10: =Q10-U10 -> -458739 | Z10: =R10-V10 -> 0 | AA10: =S10-W10 -> -458739 | AC10: =O10-AA10 -> 993146
A11: =Bonus!A11 -> 51.1137 | B11: =Bonus!B11 -> CA Water Service Co. - Bear Gulch Pump Station 18 | C11: =Bonus!G11 -> 0.86960311 | D11: =GAAP!G11 -> 0.86960311 | E11: =Bonus!I11 -> 1141051 | F11: =Bonus!F11 -> 1042229.3 | G11: =E11-F11 -> 98821.697 | I11: =GAAP!I11 -> 1141051 | J11: =GAAP!F11 -> 1042229.3 | K11: =I11-J11 -> 98821.697 | M11: =E11-I11 -> 0 | N11: =F11-J11 -> 0 | O11: =G11-K11 -> 0 | Q11: =R11+S11 -> 842122.98 | R11: =Bonus!Q11 -> 770544.87 | S11: =Bonus!S11 -> 71578.108 | U11: =V11+W11 -> 842122.98 | V11: =GAAP!Q11 -> 770544.87 | W11: =GAAP!S11 -> 71578.108 | Y11: =Q11-U11 -> 0 | Z11: =R11-V11 -> 0 | AA11: =S11-W11 -> 0 | AC11: =O11-AA11 -> 0
A12: =Bonus!A12 -> 51.1144 | B12: =Bonus!B12 -> Silicon Valley Clean Water - FEP Improvements Project | C12: =Bonus!G12 -> 0.60744172 | D12: =GAAP!G12 -> 0.60744172 | E12: =Bonus!I12 -> 9093139 | F12: =Bonus!F12 -> 8406760.8 | G12: =E12-F12 -> 686378.17 | I12: =GAAP!I12 -> 9093139 | J12: =GAAP!F12 -> 8406760.8 | K12: =I12-J12 -> 686378.17 | M12: =E12-I12 -> 0 | N12: =F12-J12 -> 0 | O12: =G12-K12 -> 0 | Q12: =R12+S12 -> 7649428.1 | R12: =Bonus!Q12 -> 7053381.4 | S12: =Bonus!S12 -> 596046.72 | U12: =V12+W12 -> 7649428.1 | V12: =GAAP!Q12 -> 7053381.4 | W12: =GAAP!S12 -> 596046.72 | Y12: =Q12-U12 -> 0 | Z12: =R12-V12 -> 0 | AA12: =S12-W12 -> 0 | AC12: =O12-AA12 -> 0
A13: =Bonus!A13 -> 51.1146 | B13: =Bonus!B13 -> National Carbon Technologies, LLC - Aymium Williams Production Facility | C13: =Bonus!G13 -> 0.92655207 | D13: =GAAP!G13 -> 0.92655207 | E13: =Bonus!I13 -> 56675079 | F13: =Bonus!F13 -> 40950686 | G13: =E13-F13 -> 15724392 | I13: =GAAP!I13 -> 56501362 | J13: =GAAP!F13 -> 40950686 | K13: =I13-J13 -> 15550675 | M13: =E13-I13 -> 173716.62 | N13: =F13-J13 -> 0 | O13: =G13-K13 -> 173716.62 | Q13: =R13+S13 -> 51031950 | R13: =Bonus!Q13 -> 36389605 | S13: =Bonus!S13 -> 14642345 | U13: =V13+W13 -> 51940281 | V13: =GAAP!Q13 -> 36389605 | W13: =GAAP!S13 -> 15550675 | Y13: =Q13-U13 -> -908330.8 | Z13: =R13-V13 -> 0 | AA13: =S13-W13 -> -908330.8 | AC13: =O13-AA13 -> 1082047.4
A14: =Bonus!A14 -> 51.1151 | B14: =Bonus!B14 -> Sonoma Valley County Sanitation Dist. - Sonoma Valley Influent Effluent Upgrade | C14: =Bonus!G14 -> 0.48846743 | D14: =GAAP!G14 -> 0.48846743 | E14: =Bonus!I14 -> 5206183.6 | F14: =Bonus!F14 -> 4923435.2 | G14: =E14-F14 -> 282748.4 | I14: =GAAP!I14 -> 5206183.6 | J14: =GAAP!F14 -> 4923435.2 | K14: =I14-J14 -> 282748.4 | M14: =E14-I14 -> 0 | N14: =F14-J14 -> 0 | O14: =G14-K14 -> 0 | Q14: =R14+S14 -> 5019039.5 | R14: =Bonus!Q14 -> 4736291.1 | S14: =Bonus!S14 -> 282748.4 | U14: =V14+W14 -> 5019039.5 | V14: =GAAP!Q14 -> 4736291.1 | W14: =GAAP!S14 -> 282748.4 | Y14: =Q14-U14 -> 0 | Z14: =R14-V14 -> 0 | AA14: =S14-W14 -> 0 | AC14: =O14-AA14 -> 0
A15: =Bonus!A15 -> 51.1152 | B15: =Bonus!B15 -> Mozingo Construction Inc - ElD Sly Park Intertie Project | C15: =Bonus!G15 -> 0.72332631 | D15: =GAAP!G15 -> 0.72332631 | E15: =Bonus!I15 -> 14448074 | F15: =Bonus!F15 -> 13474809 | G15: =E15-F15 -> 973265.21 | I15: =GAAP!I15 -> 14448074 | J15: =GAAP!F15 -> 13474809 | K15: =I15-J15 -> 973265.21 | M15: =E15-I15 -> 0 | N15: =F15-J15 -> 0 | O15: =G15-K15 -> 0 | Q15: =R15+S15 -> 13001303 | R15: =Bonus!Q15 -> 12028038 | S15: =Bonus!S15 -> 973265.21 | U15: =V15+W15 -> 13001303 | V15: =GAAP!Q15 -> 12028038 | W15: =GAAP!S15 -> 973265.21 | Y15: =Q15-U15 -> 0 | Z15: =R15-V15 -> 0 | AA15: =S15-W15 -> 0 | AC15: =O15-AA15 -> 0
A16: =Bonus!A16 -> 51.1153 | B16: =Bonus!B16 -> Linda County Water Dist. - Aeration Blower Replacement | C16: =Bonus!G16 -> 0.7360519 | D16: =GAAP!G16 -> 0.7360519 | E16: =Bonus!I16 -> 414268.17 | F16: =Bonus!F16 -> 334550.81 | G16: =E16-F16 -> 79717.365 | I16: =GAAP!I16 -> 414268.17 | J16: =GAAP!F16 -> 334550.81 | K16: =I16-J16 -> 79717.365 | M16: =E16-I16 -> 0 | N16: =F16-J16 -> 0 | O16: =G16-K16 -> 0 | Q16: =R16+S16 -> 302445.43 | R16: =Bonus!Q16 -> 235587.45 | S16: =Bonus!S16 -> 66857.976 | U16: =V16+W16 -> 302445.43 | V16: =GAAP!Q16 -> 235587.45 | W16: =GAAP!S16 -> 66857.976 | Y16: =Q16-U16 -> 0 | Z16: =R16-V16 -> 0 | AA16: =S16-W16 -> 0 | AC16: =O16-AA16 -> 0
A17: =Bonus!A17 -> 51.1154 | B17: =Bonus!B17 -> Keyes Community Services Dist. - TCP Treatment Impvmts Wells 7,8,9,10 | C17: =Bonus!G17 -> 0.95063652 | D17: =GAAP!G17 -> 0.95063652 | E17: =Bonus!I17 -> 12704150 | F17: =Bonus!F17 -> 11872343 | G17: =E17-F17 -> 831806.95 | I17: =GAAP!I17 -> 12704150 | J17: =GAAP!F17 -> 11872343 | K17: =I17-J17 -> 831806.95 | M17: =E17-I17 -> 0 | N17: =F17-J17 -> 0 | O17: =G17-K17 -> 0 | Q17: =R17+S17 -> 10325590 | R17: =Bonus!Q17 -> 9493783.4 | S17: =Bonus!S17 -> 831806.95 | U17: =V17+W17 -> 10231270 | V17: =GAAP!Q17 -> 9493783.4 | W17: =GAAP!S17 -> 737486.53 | Y17: =Q17-U17 -> 94320.423 | Z17: =R17-V17 -> 0 | AA17: =S17-W17 -> 94320.423 | AC17: =O17-AA17 -> -94320.423
A18: =Bonus!A18 -> 51.1158 | B18: =Bonus!B18 -> Schneider Electric - City of Ceres WWTP Phase 1- Schneider Electric | C18: =Bonus!G18 -> 0.54536019 | D18: =GAAP!G18 -> 0.54536019 | E18: =Bonus!I18 -> 56960.69 | F18: =Bonus!F18 -> 56960.69 | G18: =E18-F18 -> 0 | I18: =GAAP!I18 -> 56960.69 | J18: =GAAP!F18 -> 56960.69 | K18: =I18-J18 -> 0 | M18: =E18-I18 -> 0 | N18: =F18-J18 -> 0 | O18: =G18-K18 -> 0 | Q18: =R18+S18 -> 56960.69 | R18: =Bonus!Q18 -> 56960.69 | S18: =Bonus!S18 -> 0 | U18: =V18+W18 -> 56960.69 | V18: =GAAP!Q18 -> 56960.69 | W18: =GAAP!S18 -> 0 | Y18: =Q18-U18 -> 0 | Z18: =R18-V18 -> 0 | AA18: =S18-W18 -> 0 | AC18: =O18-AA18 -> 0
A19: =Bonus!A19 -> 51.1159 | B19: =Bonus!B19 -> El Dorado Irrigation Dist. - EID Reservoir A WTP Backwash-to-waste Valve Repalcement | C19: =Bonus!G19 -> 0.73204396 | D19: =GAAP!G19 -> 0.73204396 | E19: =Bonus!I19 -> 877720.7 | F19: =Bonus!F19 -> 790051.12 | G19: =E19-F19 -> 87669.584 | I19: =GAAP!I19 -> 877720.7 | J19: =GAAP!F19 -> 790051.12 | K19: =I19-J19 -> 87669.584 | M19: =E19-I19 -> 0 | N19: =F19-J19 -> 0 | O19: =G19-K19 -> 0 | Q19: =R19+S19 -> 877720.7 | R19: =Bonus!Q19 -> 790051.12 | S19: =Bonus!S19 -> 87669.584 | U19: =V19+W19 -> 877720.7 | V19: =GAAP!Q19 -> 790051.12 | W19: =GAAP!S19 -> 87669.584 | Y19: =Q19-U19 -> 0 | Z19: =R19-V19 -> 0 | AA19: =S19-W19 -> 0 | AC19: =O19-AA19 -> 0
A20: =Bonus!A20 -> 51.116 | B20: =Bonus!B20 -> City of Galt Public Works - Industrial WWTP Expansion | C20: =Bonus!G20 -> 0.14823553 | D20: =GAAP!G20 -> 0.14823553 | E20: =Bonus!I20 -> 250518.05 | F20: =Bonus!F20 -> 250518.05 | G20: =E20-F20 -> 0 | I20: =GAAP!I20 -> 260449.83 | J20: =GAAP!F20 -> 250518.05 | K20: =I20-J20 -> 9931.7807 | M20: =E20-I20 -> -9931.7807 | N20: =F20-J20 -> 0 | O20: =G20-K20 -> -9931.7807 | Q20: =R20+S20 -> 250518.05 | R20: =Bonus!Q20 -> 250518.05 | S20: =Bonus!S20 -> 0 | U20: =V20+W20 -> 260449.83 | V20: =GAAP!Q20 -> 250518.05 | W20: =GAAP!S20 -> 9931.7807 | Y20: =Q20-U20 -> -9931.7807 | Z20: =R20-V20 -> 0 | AA20: =S20-W20 -> -9931.7807 | AC20: =O20-AA20 -> 0
... A24: =Bonus!A24 -> 51.1165 | B24: =Bonus!B24 -> City of Yuba City - WTP Aquifer Storage and Recovery Well No. 3 | C24: =Bonus!G24 -> 0.0047745016 | D24: =GAAP!G24 -> 0.0047745016 | E24: =Bonus!I24 -> 23330.33 | F24: =Bonus!F24 -> 23330.33 | G24: =E24-F24 -> 0 | I24: =GAAP!I24 -> 23330.33 | J24: =GAAP!F24 -> 23330.33 | K24: =I24-J24 -> 0 | M24: =E24-I24 -> 0 | N24: =F24-J24 -> 0 | O24: =G24-K24 -> 0 | Q24: =R24+S24 -> 23330.33 | R24: =Bonus!Q24 -> 23330.33 | S24: =Bonus!S24 -> 0 | U24: =V24+W24 -> 23330.33 | V24: =GAAP!Q24 -> 23330.33 | W24: =GAAP!S24 -> 0 | Y24: =Q24-U24 -> 0 | Z24: =R24-V24 -> 0 | AA24: =S24-W24 -> 0 | AC24: =O24-AA24 -> 0
Q25: 0 | S25: =Q25-R25 -> 0 | AC25: =O25-AA25 -> 0
A26: Rocklin Open Jobs Total | E26: =SUM(E9:E25) -> 2.9208296e+08 | F26: =SUM(F9:F25) -> 2.5993861e+08 | G26: =SUM(G9:G25) -> 32144351 | I26: =SUM(I9:I25) -> 2.9130404e+08 | J26: =SUM(J9:J25) -> 2.5993861e+08 | K26: =SUM(K9:K25) -> 31365431 | M26: =SUM(M9:M25) -> 778920.69 | N26: =SUM(N9:N25) -> 0 | O26: =SUM(O9:O25) -> 778920.69 | Q26: =SUM(Q9:Q25) -> 1.1601761e+08 | R26: =SUM(R9:R25) -> 97364760 | S26: =SUM(S9:S25) -> 18652847 | U26: =SUM(U9:U25) -> 1.175122e+08 | V26: =SUM(V9:V25) -> 97364760 | W26: =SUM(W9:W25) -> 20147436 | Y26: =SUM(Y9:Y25) -> -1494589.5 | Z26: =SUM(Z9:Z25) -> 0 | AA26: =SUM(AA9:AA25) -> -1494589.5 | AC26: =O26-AA26 -> 2273510.2
AC27: =O27-AA27 -> 0
A28: Rocklin Closed Jobs | AC28: =O28-AA28 -> 0
A29: =Bonus!A29 -> 51.1133 | B29: =Bonus!B29 -> CA Water Service Co. - S. San Francisco St 1-A Pump Replacement | C29: =Bonus!G29 -> 1 | D29: =GAAP!G29 -> 1 | E29: =Bonus!I29 -> 372738 | F29: =Bonus!F29 -> 331855.28 | G29: =E29-F29 -> 40882.72 | I29: =GAAP!I29 -> 372738 | J29: =GAAP!F29 -> 331855.28 | K29: =I29-J29 -> 40882.72 | M29: =E29-I29 -> 0 | N29: =F29-J29 -> 0 | O29: =G29-K29 -> 0 | Q29: =R29+S29 -> 52253.009 | R29: =Bonus!Q29 -> 28729.87 | S29: =Bonus!S29 -> 23523.139 | U29: =V29+W29 -> 52253.009 | V29: =GAAP!Q29 -> 28729.87 | W29: =GAAP!S29 -> 23523.139 | Y29: =Q29-U29 -> 0 | Z29: =R29-V29 -> 0 | AA29: =S29-W29 -> 0 | AC29: =O29-AA29 -> 0
A30: =Bonus!A30 -> 51.1136 | B30: =Bonus!B30 -> Union Sanitary Dist - USD Plant Misc. Improvements | C30: =Bonus!G30 -> 1 | D30: =GAAP!G30 -> 1 | E30: =Bonus!I30 -> 5483550 | F30: =Bonus!F30 -> 4531817.9 | G30: =E30-F30 -> 951732.14 | I30: =GAAP!I30 -> 5483550 | J30: =GAAP!F30 -> 4531817.9 | K30: =I30-J30 -> 951732.14 | M30: =E30-I30 -> 0 | N30: =F30-J30 -> 0 | O30: =G30-K30 -> 0 | Q30: =R30+S30 -> 495311.37 | R30: =Bonus!Q30 -> 302485.02 | S30: =Bonus!S30 -> 192826.35 | U30: =V30+W30 -> 495311.37 | V30: =GAAP!Q30 -> 302485.02 | W30: =GAAP!S30 -> 192826.35 | Y30: =Q30-U30 -> 0 | Z30: =R30-V30 -> 0 | AA30: =S30-W30 -> 0 | AC30: =O30-AA30 -> 0
A31: =Bonus!A31 -> 51.1138 | B31: =Bonus!B31 -> CA Water Service Co. - Bear Gulch Pump Station 21 | C31: =Bonus!G31 -> 1 | D31: =GAAP!G31 -> 1 | E31: =Bonus!I31 -> 1120182.1 | F31: =Bonus!F31 -> 1167704.1 | G31: =E31-F31 -> -47522.08 | I31: =GAAP!I31 -> 1120182.1 | J31: =GAAP!F31 -> 1167704.1 | K31: =I31-J31 -> -47522.08 | M31: =E31-I31 -> 0 | N31: =F31-J31 -> 0 | O31: =G31-K31 -> 0 | Q31: =R31+S31 -> 255501.92 | R31: =Bonus!Q31 -> 380802.1 | S31: =Bonus!S31 -> -125300.18 | U31: =V31+W31 -> 255501.92 | V31: =GAAP!Q31 -> 380802.1 | W31: =GAAP!S31 -> -125300.18 | Y31: =Q31-U31 -> 0 | Z31: =R31-V31 -> 0 | AA31: =S31-W31 -> 0 | AC31: =O31-AA31 -> 0
A32: =Bonus!A32 -> 51.1139 | B32: =Bonus!B32 -> CA Water Service Co. - Bear Gulch Pump Station 14/29 | C32: =Bonus!G32 -> 1 | D32: =GAAP!G32 -> 1 | E32: =Bonus!I32 -> 61902 | F32: =Bonus!F32 -> 56994.44 | G32: =E32-F32 -> 4907.56 | I32: =GAAP!I32 -> 61902 | J32: =GAAP!F32 -> 56994.44 | K32: =I32-J32 -> 4907.56 | M32: =E32-I32 -> 0 | N32: =F32-J32 -> 0 | O32: =G32-K32 -> 0 | Q32: =R32+S32 -> 481.20101 | R32: =Bonus!Q32 -> 0 | S32: =Bonus!S32 -> 481.20101 | U32: =V32+W32 -> 481.20101 | V32: =GAAP!Q32 -> 0 | W32: =GAAP!S32 -> 481.20101 | Y32: =Q32-U32 -> 0 | Z32: =R32-V32 -> 0 | AA32: =S32-W32 -> 0 | AC32: =O32-AA32 -> 0
A33: =Bonus!A33 -> 51.1141 | B33: =Bonus!B33 -> City of Colfax - WWTP Algae Reduction Project | C33: =Bonus!G33 -> 1 | D33: =GAAP!G33 -> 1 | E33: =Bonus!I33 -> 3967189.8 | F33: =Bonus!F33 -> 3835094.7 | G33: =E33-F33 -> 132095.06 | I33: =GAAP!I33 -> 3967189.8 | J33: =GAAP!F33 -> 3835094.7 | K33: =I33-J33 -> 132095.06 | M33: =E33-I33 -> 0 | N33: =F33-J33 -> 0 | O33: =G33-K33 -> 0 | Q33: =R33+S33 -> 777363.73 | R33: =Bonus!Q33 -> 725188.97 | S33: =Bonus!S33 -> 52174.761 | U33: =V33+W33 -> 777363.73 | V33: =GAAP!Q33 -> 725188.97 | W33: =GAAP!S33 -> 52174.761 | Y33: =Q33-U33 -> 0 | Z33: =R33-V33 -> 0 | AA33: =S33-W33 -> 0 | AC33: =O33-AA33 -> 0
A34: =Bonus!A34 -> 51.1143 | B34: =Bonus!B34 -> Olivehurst Plumas Lake Manganese Filter Expansion | C34: =Bonus!G34 -> 1 | D34: =GAAP!G34 -> 1 | E34: =Bonus!I34 -> 1991231.4 | F34: =Bonus!F34 -> 1758132.6 | G34: =E34-F34 -> 233098.8 | I34: =GAAP!I34 -> 1991231.4 | J34: =GAAP!F34 -> 1758132.6 | K34: =I34-J34 -> 233098.8 | M34: =E34-I34 -> 0 | N34: =F34-J34 -> 0 | O34: =G34-K34 -> 0 | Q34: =R34+S34 -> 34528.637 | R34: =Bonus!Q34 -> 27441.6 | S34: =Bonus!S34 -> 7087.0371 | U34: =V34+W34 -> 34528.637 | V34: =GAAP!Q34 -> 27441.6 | W34: =GAAP!S34 -> 7087.0371 | Y34: =Q34-U34 -> 0 | Z34: =R34-V34 -> 0 | AA34: =S34-W34 -> 0 | AC34: =O34-AA34 -> 0
A35: =Bonus!A35 -> 51.1147 | B35: =Bonus!B35 -> City of Lodi-Public Works Dept. - Aeration Diffusers Replacement Project | C35: =Bonus!G35 -> 1 | D35: =GAAP!G35 -> 1 | E35: =Bonus!I35 -> 2742860.1 | F35: =Bonus!F35 -> 2548724.9 | G35: =E35-F35 -> 194135.16 | I35: =GAAP!I35 -> 2742860.1 | J35: =GAAP!F35 -> 2548724.9 | K35: =I35-J35 -> 194135.16 | M35: =E35-I35 -> 0 | N35: =F35-J35 -> 0 | O35: =G35-K35 -> 0 | Q35: =R35+S35 -> 864663.22 | R35: =Bonus!Q35 -> 798812.6 | S35: =Bonus!S35 -> 65850.625 | U35: =V35+W35 -> 864663.22 | V35: =GAAP!Q35 -> 798812.6 | W35: =GAAP!S35 -> 65850.625 | Y35: =Q35-U35 -> 0 | Z35: =R35-V35 -> 0 | AA35: =S35-W35 -> 0 | AC35: =O35-AA35 -> 0
A36: =Bonus!A36 -> 51.115 | B36: =Bonus!B36 -> Sacramento Co. Dept. of Water Resources - D49 Metro Air Park Storm Drain Pump Station Phase 2 | C36: =Bonus!G36 -> 1 | D36: =GAAP!G36 -> 1 | E36: =Bonus!I36 -> 2486231.6 | F36: =Bonus!F36 -> 2239435.1 | G36: =E36-F36 -> 246796.44 | I36: =GAAP!I36 -> 2486231.6 | J36: =GAAP!F36 -> 2239435.1 | K36: =I36-J36 -> 246796.44 | M36: =E36-I36 -> 0 | N36: =F36-J36 -> 0 | O36: =G36-K36 -> 0 | Q36: =R36+S36 -> 248682.95 | R36: =Bonus!Q36 -> 168358.34 | S36: =Bonus!S36 -> 80324.611 | U36: =V36+W36 -> 248682.95 | V36: =GAAP!Q36 -> 168358.34 | W36: =GAAP!S36 -> 80324.611 | Y36: =Q36-U36 -> 0 | Z36: =R36-V36 -> 0 | AA36: =S36-W36 -> 0 | AC36: =O36-AA36 -> 0
A37: =Bonus!A37 -> 51.1156 | B37: =Bonus!B37 -> Rocklin Overhead 2025 | C37: =Bonus!G37 -> 1 | D37: =GAAP!G37 -> 1 | E37: =Bonus!I37 -> 0 | F37: =Bonus!F37 -> 1426058.7 | G37: =E37-F37 -> -1426058.7 | I37: =GAAP!I37 -> 0 | J37: =GAAP!F37 -> 1426058.7 | K37: =I37-J37 -> -1426058.7 | M37: =E37-I37 -> 0 | N37: =F37-J37 -> 0 | O37: =G37-K37 -> 0 | Q37: =R37+S37 -> 0 | R37: =Bonus!Q37 -> 1426058.7 | S37: =Bonus!S37 -> -1426058.7 | U37: =V37+W37 -> 0 | V37: =GAAP!Q37 -> 1426058.7 | W37: =GAAP!S37 -> -1426058.7 | Y37: =Q37-U37 -> 0 | Z37: =R37-V37 -> 0 | AA37: =S37-W37 -> 0 | AC37: =O37-AA37 -> 0
A38: =Bonus!A38 -> 51.1157 | B38: =Bonus!B38 -> Rocklin Estimating 2025 | C38: =Bonus!G38 -> 1 | D38: =GAAP!G38 -> 1 | E38: =Bonus!I38 -> 0 | F38: =Bonus!F38 -> 613546.52 | G38: =E38-F38 -> -613546.52 | I38: =GAAP!I38 -> 0 | J38: =GAAP!F38 -> 613546.52 | K38: =I38-J38 -> -613546.52 | M38: =E38-I38 -> 0 | N38: =F38-J38 -> 0 | O38: =G38-K38 -> 0 | Q38: =R38+S38 -> 0 | R38: =Bonus!Q38 -> 613546.52 | S38: =Bonus!S38 -> -613546.52 | U38: =V38+W38 -> 0 | V38: =GAAP!Q38 -> 613546.52 | W38: =GAAP!S38 -> -613546.52 | Y38: =Q38-U38 -> 0 | Z38: =R38-V38 -> 0 | AA38: =S38-W38 -> 0 | AC38: =O38-AA38 -> 0
AC39: =O39-AA39 -> 0
A40: Rocklin Closed Jobs Total | E40: =SUM(E29:E39) -> 18225885 | F40: =SUM(F29:F39) -> 18509364 | G40: =SUM(G29:G39) -> -283479.41 | I40: =SUM(I29:I39) -> 18225885 | J40: =SUM(J29:J39) -> 18509364 | K40: =SUM(K29:K39) -> -283479.41 | M40: =SUM(M29:M39) -> 0 | N40: =SUM(N29:N39) -> 0 | O40: =SUM(O29:O39) -> 0 | Q40: =SUM(Q29:Q39) -> 2728786 | R40: =SUM(R29:R39) -> 4471423.7 | S40: =SUM(S29:S39) -> -1742637.7 | U40: =SUM(U29:U39) -> 2728786 | V40: =SUM(V29:V39) -> 4471423.7 | W40: =SUM(W29:W39) -> -1742637.7 | Y40: =SUM(Y29:Y39) -> 0 | Z40: =SUM(Z29:Z39) -> 0 | AA40: =SUM(AA29:AA39) -> 0 | AC40: =O40-AA40 -> 0
AC41: =O41-AA41 -> 0
A42: Rocklin Total | E42: =E26+E40 -> 3.1030884e+08 | F42: =F26+F40 -> 2.7844797e+08 | G42: =G26+G40 -> 31860872 | I42: =I26+I40 -> 3.0952992e+08 | J42: =J26+J40 -> 2.7844797e+08 | K42: =K26+K40 -> 31081951 | M42: =M26+M40 -> 778920.69 | N42: =N26+N40 -> 0 | O42: =O26+O40 -> 778920.69 | Q42: =Q26+Q40 -> 1.1874639e+08 | R42: =R26+R40 -> 1.0183618e+08 | S42: =S26+S40 -> 16910209 | U42: =U26+U40 -> 1.2024098e+08 | V42: =V26+V40 -> 1.0183618e+08 | W42: =W26+W40 -> 18404798 | Y42: =Y26+Y40 -> -1494589.5 | Z42: =Z26+Z40 -> 0 | AA42: =AA26+AA40 -> -1494589.5 | AC42: =O42-AA42 -> 2273510.2
A44: Fresno Open Jobs
A45: =Bonus!A44 -> 52.8563 | B45: =Bonus!B44 -> City of Santa Cruz - Graham Hill WTP Facility Improvements - Phase 1 | C45: =Bonus!G44 -> 0.97534821 | D45: =GAAP!G44 -> 1 | E45: =Bonus!I44 -> 1152462.3 | F45: =Bonus!F44 -> 859077.05 | G45: =E45-F45 -> 293385.24 | I45: =GAAP!I44 -> 1134038.1 | J45: =GAAP!F44 -> 859077.05 | K45: =I45-J45 -> 274961.08 | M45: =E45-I45 -> 18424.16 | N45: =F45-J45 -> 0 | O45: =G45-K45 -> 18424.16 | Q45: =R45+S45 -> 167405.78 | R45: =Bonus!Q44 -> 138210.3 | S45: =Bonus!S44 -> 29195.48 | U45: =V45+W45 -> 218705.64 | V45: =GAAP!Q44 -> 138210.3 | W45: =GAAP!S44 -> 80495.34 | Y45: =Q45-U45 -> -51299.86 | Z45: =R45-V45 -> 0 | AA45: =S45-W45 -> -51299.86 | AC45: =O45-AA45 -> 69724.02
...

Sheet Job Status
A1: W. M. Lyles Co. | Q1: A | R1: Opened in PY, Closed in CY
A2: Job Status Analysis | Q2: B | R2: Opened in PY, Still Open:
A3: For the Month Ended December 31, 2025 | I3: =Backlog!A3 -> 46022 | Q3: C | R3: Open in CY, Closed in CY:
Q4: D | R4: Opened in CY, Still Open:
C5: Billed | D5: Remaining | E5: Total | F5: Cost | G5: Estimate | I5: Projected | L5: Prior | M5: Net | Q5: O | R5: Overhead Jobs
C6: To | D6: To | E6: Contract | F6: Incurred | G6: Cost To | H6: Total Estimated | I6: Final | J6: Percent | K6: Job to Date | L6: Amount | M6: Change | Q6: U | R6: Under $250,000
A7: Job No. | B7: Project Name | C7: Date | D7: Bill | E7: Amount | F7: To Date | G7: Complete | H7: Cost | I7: Profit/(Loss) | J7: Complete | K7: Profit | L7: Claimed | Q7: W | R7: W Jobs
A8: Jobs with Contract Amounts greater than $250,000 | Q8: Print this worksheet in B&W!
A10: Opened in PY, Closed in CY: | N10: Opened | O10: Closed | P10: Size | Q10: Section
A11: =+GAAP!A29 -> 51.1133 | B11: =+GAAP!B29 -> CA Water Service Co. - S. San Francisco St 1-A Pump Replacement | C11: =+GAAP!J29 -> 372738 | D11: =+E11-C11 -> 0 | E11: =+GAAP!C29 -> 372738 | F11: =+GAAP!F29 -> 331855.28 | G11: =+H11-F11 -> 0 | H11: =+E11-I11 -> 331855.28 | I11: =+GAAP!E29 -> 40882.72 | J11: =+GAAP!G29 -> 1 | K11: =+GAAP!H29 -> 40882.72 | L11: =+GAAP!P29 -> 17359.581 | M11: =+K11-L11 -> 23523.139 | N11: =GAAP!T29 -> 2023 | O11: =GAAP!U29 -> 2025 | P11: =+GAAP!V29 -> .
A12: =+GAAP!A30 -> 51.1136 | B12: =+GAAP!B30 -> Union Sanitary Dist - USD Plant Misc. Improvements | C12: =+GAAP!J30 -> 5483550 | D12: =+E12-C12 -> 0 | E12: =+GAAP!C30 -> 5483550 | F12: =+GAAP!F30 -> 4531817.9 | G12: =+H12-F12 -> 0 | H12: =+E12-I12 -> 4531817.9 | I12: =+GAAP!E30 -> 951732.14 | J12: =+GAAP!G30 -> 1 | K12: =+GAAP!H30 -> 951732.14 | L12: =+GAAP!P30 -> 758905.79 | M12: =+K12-L12 -> 192826.35 | N12: =GAAP!T30 -> 2023 | O12: =GAAP!U30 -> 2025 | P12: =+GAAP!V30 -> .
A13: =+GAAP!A31 -> 51.1138 | B13: =+GAAP!B31 -> CA Water Service Co. - Bear Gulch Pump Station 21 | C13: =+GAAP!J31 -> 1120182.1 | D13: =+E13-C13 -> 0 | E13: =+GAAP!C31 -> 1120182.1 | F13: =+GAAP!F31 -> 1167704.1 | G13: =+H13-F13 -> 0 | H13: =+E13-I13 -> 1167704.1 | I13: =+GAAP!E31 -> -47522.08 | J13: =+GAAP!G31 -> 1 | K13: =+GAAP!H31 -> -47522.08 | L13: =+GAAP!P31 -> 77778.099 | M13: =+K13-L13 -> -125300.18 | N13: =GAAP!T31 -> 2023 | O13: =GAAP!U31 -> 2025 | P13: =+GAAP!V31 -> .
A14: =+GAAP!A33 -> 51.1141 | B14: =+GAAP!B33 -> City of Colfax - WWTP Algae Reduction Project | C14: =+GAAP!J33 -> 3967189.8 | D14: =+E14-C14 -> 0 | E14: =+GAAP!C33 -> 3967189.8 | F14: =+GAAP!F33 -> 3835094.7 | G14: =+H14-F14 -> 0 | H14: =+E14-I14 -> 3835094.7 | I14: =+GAAP!E33 -> 132095.06 | J14: =+GAAP!G33 -> 1 | K14: =+GAAP!H33 -> 132095.06 | L14: =+GAAP!P33 -> 79920.299 | M14: =+K14-L14 -> 52174.761 | N14: =GAAP!T33 -> 2023 | O14: =GAAP!U33 -> 2025 | P14: =+GAAP!V33 -> .
A15: =+GAAP!A34 -> 51.1143 | B15: =+GAAP!B34 -> Olivehurst Plumas Lake Manganese Filter Expansion | C15: =+GAAP!J34 -> 1991231.4 | D15: =+E15-C15 -> 0 | E15: =+GAAP!C34 -> 1991231.4 | F15: =+GAAP!F34 -> 1758132.6 | G15: =+H15-F15 -> 0 | H15: =+E15-I15 -> 1758132.6 | I15: =+GAAP!E34 -> 233098.8 | J15: =+GAAP!G34 -> 1 | K15: =+GAAP!H34 -> 233098.8 | L15: =+GAAP!P34 -> 226011.76 | M15: =+K15-L15 -> 7087.0371 | N15: =GAAP!T34 -> 2023 | O15: =GAAP!U34 -> 2025 | P15: =+GAAP!V34 -> .
A16: =+GAAP!A35 -> 51.1147 | B16: =+GAAP!B35 -> City of Lodi-Public Works Dept. - Aeration Diffusers Replacement Project | C16: =+GAAP!J35 -> 2742860.1 | D16: =+E16-C16 -> 0 | E16: =+GAAP!C35 -> 2742860.1 | F16: =+GAAP!F35 -> 2548724.9 | G16: =+H16-F16 -> 0 | H16: =+E16-I16 -> 2548724.9 | I16: =+GAAP!E35 -> 194135.16 | J16: =+GAAP!G35 -> 1 | K16: =+GAAP!H35 -> 194135.16 | L16: =+GAAP!P35 -> 128284.54 | M16: =+K16-L16 -> 65850.625 | N16: =GAAP!T35 -> 2023 | O16: =GAAP!U35 -> 2025 | P16: =+GAAP!V35 -> .
A17: =+GAAP!A36 -> 51.115 | B17: =+GAAP!B36 -> Sacramento Co. Dept. of Water Resources - D49 Metro Air Park Storm Drain Pump Station Phase 2 | C17: =+GAAP!J36 -> 2486231.6 | D17: =+E17-C17 -> 0 | E17: =+GAAP!C36 -> 2486231.6 | F17: =+GAAP!F36 -> 2239435.1 | G17: =+H17-F17 -> 0 | H17: =+E17-I17 -> 2239435.1 | I17: =+GAAP!E36 -> 246796.44 | J17: =+GAAP!G36 -> 1 | K17: =+GAAP!H36 -> 246796.44 | L17: =+GAAP!P36 -> 166471.83 | M17: =+K17-L17 -> 80324.611 | N17: =GAAP!T36 -> 2024 | O17: =GAAP!U36 -> 2025 | P17: =+GAAP!V36 -> .
A18: =+GAAP!A68 -> 52.8567 | B18: =+GAAP!B68 -> City of Modesto - Grayson Well 69 | C18: =+GAAP!J68 -> 3059859 | D18: =+E18-C18 -> 0 | E18: =+GAAP!C68 -> 3059859 | F18: =+GAAP!F68 -> 3128023.9 | G18: =+H18-F18 -> 0 | H18: =+E18-I18 -> 3128023.9 | I18: =+GAAP!E68 -> -68164.94 | J18: =+GAAP!G68 -> 1 | K18: =+GAAP!H68 -> -68164.94 | L18: =+GAAP!P68 -> -83000 | M18: =+K18-L18 -> 14835.06 | N18: =GAAP!T68 -> 2021 | O18: =GAAP!U68 -> 2025 | P18: =+GAAP!V68 -> .
A19: =+GAAP!A69 -> 52.8604 | B19: =+GAAP!B69 -> City of Atwater - Project No. 20-2, Well 20-A TCP Mitigation | C19: =+GAAP!J69 -> 5095691 | D19: =+E19-C19 -> 0 | E19: =+GAAP!C69 -> 5095691 | F19: =+GAAP!F69 -> 4572503.2 | G19: =+H19-F19 -> 0 | H19: =+E19-I19 -> 4572503.2 | I19: =+GAAP!E69 -> 523187.74 | J19: =+GAAP!G69 -> 1 | K19: =+GAAP!H69 -> 523187.74 | L19: =+GAAP!P69 -> 329989.13 | M19: =+K19-L19 -> 193198.61 | N19: =GAAP!T69 -> 2022 | O19: =GAAP!U69 -> 2025 | P19: =+GAAP!V69 -> .
A20: =+GAAP!A70 -> 52.8628 | B20: =+GAAP!B70 -> City of Tulare - Well 4-3 Equipping & I Drive Pipeline Proj. | C20: =+GAAP!J70 -> 5213345.5 | D20: =+E20-C20 -> 0 | E20: =+GAAP!C70 -> 5213345.5 | F20: =+GAAP!F70 -> 4745798.5 | G20: =+H20-F20 -> 0 | H20: =+E20-I20 -> 4745798.5 | I20: =+GAAP!E70 -> 467546.97 | J20: =+GAAP!G70 -> 1 | K20: =+GAAP!H70 -> 467546.97 | L20: =+GAAP!P70 -> 197224.75 | M20: =+K20-L20 -> 270322.22 | N20: =GAAP!T70 -> 2023 | O20: =GAAP!U70 -> 2025 | P20: =+GAAP!V70 -> .
A21: =+GAAP!A71 -> 52.8631 | B21: =+GAAP!B71 -> Gunner Ranch, Inc. - Well 1 Equipping and Site Improvements | C21: =+GAAP!J71 -> 2560650.1 | D21: =+E21-C21 -> 0 | E21: =+GAAP!C71 -> 2560650.1 | F21: =+GAAP!F71 -> 2448658.3 | G21: =+H21-F21 -> 0 | H21: =+E21-I21 -> 2448658.3 | I21: =+GAAP!E71 -> 111991.88 | J21: =+GAAP!G71 -> 1 | K21: =+GAAP!H71 -> 111991.88 | L21: =+GAAP!P71 -> 73003.701 | M21: =+K21-L21 -> 38988.179 | N21: =GAAP!T71 -> 2023 | O21: =GAAP!U71 -> 2025 | P21: =+GAAP!V71 -> .
A22: =+GAAP!A72 -> 52.8652 | B22: =+GAAP!B72 -> California Water Service Co. - Salinas 77 Booster Station | C22: =+GAAP!J72 -> 1290184 | D22: =+E22-C22 -> 0 | E22: =+GAAP!C72 -> 1290184 | F22: =+GAAP!F72 -> 1039376.1 | G22: =+H22-F22 -> 0 | H22: =+E22-I22 -> 1039376.1 | I22: =+GAAP!E72 -> 250807.92 | J22: =+GAAP!G72 -> 1 | K22: =+GAAP!H72 -> 250807.92 | L22: =+GAAP!P72 -> 170698.84 | M22: =+K22-L22 -> 80109.083 | N22: =GAAP!T72 -> 2024 | O22: =GAAP!U72 -> 2025 | P22: =+GAAP!V72 -> .
A23: =+GAAP!A73 -> 52.8658 | B23: =+GAAP!B73 -> California Water Service Co. - Visalia Station 98 Water Storage Tank & Booster Site | C23: =+GAAP!J73 -> 1870915 | D23: =+E23-C23 -> 0 | E23: =+GAAP!C73 -> 1870915 | F23: =+GAAP!F73 -> 1633530.2 | G23: =+H23-F23 -> 0 | H23: =+E23-I23 -> 1633530.2 | I23: =+GAAP!E73 -> 237384.78 | J23: =+GAAP!G73 -> 1 | K23: =+GAAP!H73 -> 237384.78 | L23: =+GAAP!P73 -> 145886.61 | M23: =+K23-L23 -> 91498.175 | N23: =GAAP!T73 -> 2023 | O23: =GAAP!U73 -> 2025 | P23: =+GAAP!V73 -> .
A24: =+GAAP!A74 -> 52.8663 | B24: =+GAAP!B74 -> Root Creek Water Dist. - Ag Well 277 Conversion Project | C24: =+GAAP!J74 -> 1641800 | D24: =+E24-C24 -> 0 | E24: =+GAAP!C74 -> 1641800 | F24: =+GAAP!F74 -> 1379688.3 | G24: =+H24-F24 -> 0 | H24: =+E24-I24 -> 1379688.3 | I24: =+GAAP!E74 -> 262111.72 | J24: =+GAAP!G74 -> 1 | K24: =+GAAP!H74 -> 262111.72 | L24: =+GAAP!P74 -> 42676.951 | M24: =+K24-L24 -> 219434.77 | N24: =GAAP!T74 -> 2024 | O24: =GAAP!U74 -> 2025 | P24: =+GAAP!V74 -> .
A25: =+GAAP!A75 -> 52.8667 | B25: =+GAAP!B75 -> California Water Service Co. - Cal Water Salinas Station 33 | C25: =+GAAP!J75 -> 314085.77 | D25: =+E25-C25 -> 0 | E25: =+GAAP!C75 -> 314085.77 | F25: =+GAAP!F75 -> 290726.11 | G25: =+H25-F25 -> 0 | H25: =+E25-I25 -> 290726.11 | I25: =+GAAP!E75 -> 23359.66 | J25: =+GAAP!G75 -> 1 | K25: =+GAAP!H75 -> 23359.66 | L25: =+GAAP!P75 -> 26868.865 | M25: =+K25-L25 -> -3509.2053 | N25: =GAAP!T75 -> 2024 | O25: =GAAP!U75 -> 2025 | P25: =+GAAP!V75 -> .
A26: =+GAAP!A76 -> 52.867 | B26: =+GAAP!B76 -> California Water Service Co. - Cal Water - King City Station 10 | C26: =+GAAP!J76 -> 274166.01 | D26: =+E26-C26 -> 0 | E26: =+GAAP!C76 -> 274166.01 | F26: =+GAAP!F76 -> 267282.05 | G26: =+H26-F26 -> 0 | H26: =+E26-I26 -> 267282.05 | I26: =+GAAP!E76 -> 6883.96 | J26: =+GAAP!G76 -> 1 | K26: =+GAAP!H76 -> 6883.96 | L26: =+GAAP!P76 -> 10404.436 | M26: =+K26-L26 -> -3520.4756 | N26: =GAAP!T76 -> 2024 | O26: =GAAP!U76 -> 2025 | P26: =+GAAP!V76 -> .
A27: =+GAAP!A77 -> 52.8674 | B27: =+GAAP!B77 -> City of Hanford - WWTP Standby Influent Pump Install | C27: =+GAAP!J77 -> 279244 | D27: =+E27-C27 -> 0 | E27: =+GAAP!C77 -> 279244 | F27: =+GAAP!F77 -> 251088.2 | G27: =+H27-F27 -> 0 | H27: =+E27-I27 -> 251088.2 | I27: =+GAAP!E77 -> 28155.8 | J27: =+GAAP!G77 -> 1 | K27: =+GAAP!H77 -> 28155.8 | L27: =+GAAP!P77 -> 15534.584 | M27: =+K27-L27 -> 12621.216 | N27: =GAAP!T77 -> 2024 | O27: =GAAP!U77 -> 2025 | P27: =+GAAP!V77 -> .
A28: =+GAAP!A78 -> 52.8677 | B28: =+GAAP!B78 -> Gunner Ranch, Inc. - CSA 22C Tank and PW2 Site Improvements | C28: =+GAAP!J78 -> 796055.3 | D28: =+E28-C28 -> 0 | E28: =+GAAP!C78 -> 796055.3 | F28: =+GAAP!F78 -> 689831.96 | G28: =+H28-F28 -> 0 | H28: =+E28-I28 -> 689831.96 | I28: =+GAAP!E78 -> 106223.34 | J28: =+GAAP!G78 -> 1 | K28: =+GAAP!H78 -> 106223.34 | L28: =+GAAP!P78 -> 0 | M28: =+K28-L28 -> 106223.34 | N28: =GAAP!T78 -> 2024 | O28: =GAAP!U78 -> 2025 | P28: =+GAAP!V78 -> .
A29: =+GAAP!A112 -> 53.2004 | B29: =+GAAP!B112 -> City of Millbrae - Millbrae Sludge Thickener & Digester No. 2 Rehab Project | C29: =+GAAP!J112 -> 1173753.5 | D29: =+E29-C29 -> 0 | E29: =+GAAP!C112 -> 1173753.5 | F29: =+GAAP!F112 -> 980791.05 | G29: =+H29-F29 -> 0 | H29: =+E29-I29 -> 980791.05 | I29: =+GAAP!E112 -> 192962.42 | J29: =+GAAP!G112 -> 1 | K29: =+GAAP!H112 -> 192962.42 | L29: =+GAAP!P112 -> 0 | M29: =+K29-L29 -> 192962.42 | N29: =GAAP!T112 -> 2024 | O29: =GAAP!U112 -> 2025 | P29: =+GAAP!V112 -> .
A30: =+GAAP!A157 -> 54.9099 | B30: =+GAAP!B157 -> Laguna County Sanitation Dist. - Phase 1 Plant Upgrade | C30: =+GAAP!J157 -> 55712110 | D30: =+E30-C30 -> 0 | E30: =+GAAP!C157 -> 55712110 | F30: =+GAAP!F157 -> 45328893 | G30: =+H30-F30 -> 0 | H30: =+E30-I30 -> 45328893 | I30: =+GAAP!E157 -> 10383217 | J30: =+GAAP!G157 -> 1 | K30: =+GAAP!H157 -> 10383217 | L30: =+GAAP!P157 -> 10372752 | M30: =+K30-L30 -> 10465.739 | N30: =GAAP!T157 -> 2020 | O30: =GAAP!U157 -> 2025 | P30: =+GAAP!V157 -> .
A31: =+GAAP!A158 -> 54.9172 | B31: =+GAAP!B158 -> Calif. Rail Bldrs LLC - SWSD Distribution System Conflict | C31: =+GAAP!J158 -> 24160002 | D31: =+E31-C31 -> 0 | E31: =+GAAP!C158 -> 24160002 | F31: =+GAAP!F158 -> 21018432 | G31: =+H31-F31 -> 0 | H31: =+E31-I31 -> 21018432 | I31: =+GAAP!E158 -> 3141570.2 | J31: =+GAAP!G158 -> 1 | K31: =+GAAP!H158 -> 3141570.2 | L31: =+GAAP!P158 -> 3107901.8 | M31: =+K31-L31 -> 33668.4 | N31: =GAAP!T158 -> 2021 | O31: =GAAP!U158 -> 2025 | P31: =+GAAP!V158 -> .
A32: =+GAAP!A159 -> 54.9216 | B32: =+GAAP!B159 -> CA Dept. of Corr. - Water Treatment Improvements | C32: =+GAAP!J159 -> 2472164 | D32: =+E32-C32 -> 0 | E32: =+GAAP!C159 -> 2472164 | F32: =+GAAP!F159 -> 2286264.4 | G32: =+H32-F32 -> 0 | H32: =+E32-I32 -> 2286264.4 | I32: =+GAAP!E159 -> 185899.62 | J32: =+GAAP!G159 -> 1 | K32: =+GAAP!H159 -> 185899.62 | L32: =+GAAP!P159 -> 140849.75 | M32: =+K32-L32 -> 45049.866 | N32: =GAAP!T159 -> 2022 | O32: =GAAP!U159 -> 2025 | P32: =+GAAP!V159 -> .
A33: =+GAAP!A160 -> 54.9246 | B33: =+GAAP!B160 -> Kern County Water Agency - Well 38 & 39 Well Equiping Project | C33: =+GAAP!J160 -> 1777852 | D33: =+E33-C33 -> 0 | E33: =+GAAP!C160 -> 1777852 | F33: =+GAAP!F160 -> 1708475.3 | G33: =+H33-F33 -> 0 | H33: =+E33-I33 -> 1708475.3 | I33: =+GAAP!E160 -> 69376.68 | J33: =+GAAP!G160 -> 1 | K33: =+GAAP!H160 -> 69376.68 | L33: =+GAAP!P160 -> 69196.454 | M33: =+K33-L33 -> 180.22572 | N33: =GAAP!T160 -> 2022 | O33: =GAAP!U160 -> 2025 | P33: =+GAAP!V160 -> .
A34: =+GAAP!A162 -> 54.9279 | B34: =+GAAP!B162 -> City of Bakersfield Public Works - Sewer Lift Station Rehabilitation | C34: =+GAAP!J162 -> 3216240 | D34: =+E34-C34 -> 0 | E34: =+GAAP!C162 -> 3216240 | F34: =+GAAP!F162 -> 3153237.4 | G34: =+H34-F34 -> 0 | H34: =+E34-I34 -> 3153237.4 | I34: =+GAAP!E162 -> 63002.61 | J34: =+GAAP!G162 -> 1 | K34: =+GAAP!H162 -> 63002.61 | L34: =+GAAP!P162 -> -15000 | M34: =+K34-L34 -> 78002.61 | N34: =GAAP!T162 -> 2023 | O34: =GAAP!U162 -> 2025 | P34: =+GAAP!V162 -> .
A35: =+GAAP!A165 -> 54.9309 | B35: =+GAAP!B165 -> Teviston Community Services Dist. - Teviston Drought Resilience Water System Impr | C35: =+GAAP!J165 -> 3968668.9 | D35: =+E35-C35 -> 0 | E35: =+GAAP!C165 -> 3968668.9 | F35: =+GAAP!F165 -> 3790858.3 | G35: =+H35-F35 -> 0 | H35: =+E35-I35 -> 3790858.3 | I35: =+GAAP!E165 -> 177810.56 | J35: =+GAAP!G165 -> 1 | K35: =+GAAP!H165 -> 177810.56 | L35: =+GAAP!P165 -> 62853.416 | M35: =+K35-L35 -> 114957.14 | N35: =GAAP!T165 -> 2024 | O35: =GAAP!U165 -> 2025 | P35: =+GAAP!V165 -> .
A36: =+GAAP!A168 -> 54.9333 | B36: =+GAAP!B168 -> Semitropic Water Storage Dist. - SWSD 2 Hydro Turbine Repair Project | C36: =+GAAP!J168 -> 427464.77 | D36: =+E36-C36 -> 0 | E36: =+GAAP!C168 -> 427464.77 | F36: =+GAAP!F168 -> 371915.26 | G36: =+H36-F36 -> 0 | H36: =+E36-I36 -> 371915.26 | I36: =+GAAP!E168 -> 55549.51 | J36: =+GAAP!G168 -> 1 | K36: =+GAAP!H168 -> 55549.51 | L36: =+GAAP!P168 -> 14888.68 | M36: =+K36-L36 -> 40660.83 | N36: =GAAP!T168 -> 2024 | O36: =GAAP!U168 -> 2025 | P36: =+GAAP!V168 -> .
A37: =+GAAP!A170 -> 54.9341 | B37: =+GAAP!B170 -> Nipomo Community Service Dist. - Water Project Interconnection Improvements | C37: =+GAAP!J170 -> 1251279 | D37: =+E37-C37 -> 0 | E37: =+GAAP!C170 -> 1251279 | F37: =+GAAP!F170 -> 1063532.4 | G37: =+H37-F37 -> 0 | H37: =+E37-I37 -> 1063532.4 | I37: =+GAAP!E170 -> 187746.6 | J37: =+GAAP!G170 -> 1 | K37: =+GAAP!H170 -> 187746.6 | L37: =+GAAP!P170 -> 9297.3859 | M37: =+K37-L37 -> 178449.21 | N37: =GAAP!T170 -> 2024 | O37: =GAAP!U170 -> 2025 | P37: =+GAAP!V170 -> .
A38: =+GAAP!A173 -> 54.9349 | B38: =+GAAP!B173 -> North of River Sanitary Dist. No. 1 - Sanitary Sewer Rehabilitation Package A | C38: =+GAAP!J173 -> 290129 | D38: =+E38-C38 -> 0 | E38: =+GAAP!C173 -> 290129 | F38: =+GAAP!F173 -> 197889.31 | G38: =+H38-F38 -> 0 | H38: =+E38-I38 -> 197889.31 | I38: =+GAAP!E173 -> 92239.69 | J38: =+GAAP!G173 -> 1 | K38: =+GAAP!H173 -> 92239.69 | L38: =+GAAP!P173 -> 4519.6837 | M38: =+K38-L38 -> 87720.006 | N38: =GAAP!T173 -> 2024 | O38: =GAAP!U173 -> 2025 | P38: =+GAAP!V173 -> .
A39: =+GAAP!A180 -> 54.9358 | B39: =+GAAP!B180 -> Arvin Edison Water Storage Dist. - Frick Unit - Phase I Turnout | C39: =+GAAP!J180 -> 1147640 | D39: =+E39-C39 -> 0 | E39: =+GAAP!C180 -> 1147640 | F39: =+GAAP!F180 -> 1125399.8 | G39: =+H39-F39 -> 0 | H39: =+E39-I39 -> 1125399.8 | I39: =+GAAP!E180 -> 22240.17 | J39: =+GAAP!G180 -> 1 | K39: =+GAAP!H180 -> 22240.17 | L39: =+GAAP!P180 -> 15917.551 | M39: =+K39-L39 -> 6322.6193 | N39: =GAAP!T180 -> 2024 | O39: =GAAP!U180 -> 2025 | P39: =+GAAP!V180 -> .
A40: =+GAAP!A183 -> 54.9362 | B40: =+GAAP!B183 -> Cawelo Water Dist. - Remove and Replace 24” and 18” Well Line | C40: =+GAAP!J183 -> 425035.04 | D40: =+E40-C40 -> 0 | E40: =+GAAP!C183 -> 425035.04 | F40: =+GAAP!F183 -> 375601.24 | G40: =+H40-F40 -> 0 | H40: =+E40-I40 -> 375601.24 | I40: =+GAAP!E183 -> 49433.8 | J40: =+GAAP!G183 -> 1 | K40: =+GAAP!H183 -> 49433.8 | L40: =+GAAP!P183 -> 0 | M40: =+K40-L40 -> 49433.8 | N40: =GAAP!T183 -> 2024 | O40: =GAAP!U183 -> 2025 | P40: =+GAAP!V183 -> .
A41: =+GAAP!A240 -> 55.123 | B41: =+GAAP!B240 -> Anaergia Technologies - VVWRA - DAF 3 Replacement | C41: =+GAAP!J240 -> 2273682.7 | D41: =+E41-C41 -> 0 | E41: =+GAAP!C240 -> 2273682.7 | F41: =+GAAP!F240 -> 1665145.3 | G41: =+H41-F41 -> 0 | H41: =+E41-I41 -> 1665145.3 | I41: =+GAAP!E240 -> 608537.39 | J41: =+GAAP!G240 -> 1 | K41: =+GAAP!H240 -> 608537.39 | L41: =+GAAP!P240 -> 480252.03 | M41: =+K41-L41 -> 128285.36 | N41: =GAAP!T240 -> 2023 | O41: =GAAP!U240 -> 2025 | P41: =+GAAP!V240 -> .
...

Sheet GAAP WIP
A1: W.M. Lyles Co.
A2: WORK IN PROCESS-GAAP BASIS
A3: =+GAAP!A4 -> For the Month Period Ended 12/31/2025
C4: AMOUNT | D4: REMAINING | E4: TOTAL | F4: COSTS | G4: ESTIMATED | H4: TOTAL | I4: TOTAL | J4: % OF | L4: OVER
C5: BILLED | D5: TO BE | E5: ESTIMATED | F5: INCURED | G5: COSTS TO | H5: ESTIMATED | I5: ESTIMATED | J5: COMPLETION | K5: PROFIT / | L5: (UNDER)
A6: JOB | C6: TO DATE | D6: BILLED | E6: CONTRACT | F6: TO DATE | G6: COMPLETE | H6: COSTS | I6: PROFIT | J6: COST/COST | K6: LOSS | L6: BILLIING
A7: =+GAAP!A9 -> 51.1108 | B7: =IF(GAAP!$G9<2,+GAAP!B9," " ) -> City of Stockton - RWCF Phase 2A/2B | C7: =IF(GAAP!$G9<2,+GAAP!J9," " ) -> 94045648 | D7: =IF(GAAP!$G9<2,+GAAP!M9," " ) -> 0 | E7: =IF(GAAP!$G9<2,+GAAP!C9," " ) -> 94045648 | F7: =IF(GAAP!$G9<2,+GAAP!F9," " ) -> 89805618 | G7: =IF(GAAP!$G9<2,+GAAP!L9," " ) -> 0 | H7: =IF(GAAP!$G9<2,+GAAP!D9," " ) -> 89805618 | I7: =IF(GAAP!$G9<2,+GAAP!E9," " ) -> 4240030.1 | J7: =IF(GAAP!$G9<2,+GAAP!G9," " ) -> 1 | K7: =IF(GAAP!$G9<2,+GAAP!H9," " ) -> 4240030.1 | L7: =+GAAP!K9 -> 0 | S7: =K7-'Bonus WIP'!K8 -> -80728.85 | T7: =L7-'Bonus WIP'!L8 -> 80728.85
A8: =+GAAP!A10 -> 51.1129 | B8: =IF(GAAP!$G10<2,+GAAP!B10," " ) -> Union Sanit. Dist - Enhanced Trtmnt & Site Upgrd Ph. 1A Aeration Basin | C8: =IF(GAAP!$G10<2,+GAAP!J10," " ) -> 96918207 | D8: =IF(GAAP!$G10<2,+GAAP!M10," " ) -> 29565374 | E8: =IF(GAAP!$G10<2,+GAAP!C10," " ) -> 1.2648358e+08 | F8: =IF(GAAP!$G10<2,+GAAP!F10," " ) -> 87315159 | G8: =IF(GAAP!$G10<2,+GAAP!L10," " ) -> 27918422 | H8: =IF(GAAP!$G10<2,+GAAP!D10," " ) -> 1.1523358e+08 | I8: =IF(GAAP!$G10<2,+GAAP!E10," " ) -> 11250000 | J8: =IF(GAAP!$G10<2,+GAAP!G10," " ) -> 0.75772321 | K8: =IF(GAAP!$G10<2,+GAAP!H10," " ) -> 8524386.2 | L8: =+GAAP!K10 -> 1078661.5 | S8: =K8-'Bonus WIP'!K9 -> -534407 | T8: =L8-'Bonus WIP'!L9 -> 534407
A9: =+GAAP!A11 -> 51.1137 | B9: =IF(GAAP!$G11<2,+GAAP!B11," " ) -> CA Water Service Co. - Bear Gulch Pump Station 18 | C9: =IF(GAAP!$G11<2,+GAAP!J11," " ) -> 1121900 | D9: =IF(GAAP!$G11<2,+GAAP!M11," " ) -> 190251.45 | E9: =IF(GAAP!$G11<2,+GAAP!C11," " ) -> 1312151.5 | F9: =IF(GAAP!$G11<2,+GAAP!F11," " ) -> 1042229.3 | G9: =IF(GAAP!$G11<2,+GAAP!L11," " ) -> 156282.17 | H9: =IF(GAAP!$G11<2,+GAAP!D11," " ) -> 1198511.5 | I9: =IF(GAAP!$G11<2,+GAAP!E11," " ) -> 113640 | J9: =IF(GAAP!$G11<2,+GAAP!G11," " ) -> 0.86960311 | K9: =IF(GAAP!$G11<2,+GAAP!H11," " ) -> 98821.697 | L9: =+GAAP!K11 -> -19150.977 | S9: =K9-'Bonus WIP'!K10 -> 0 | T9: =L9-'Bonus WIP'!L10 -> 0
A10: =+GAAP!A12 -> 51.1144 | B10: =IF(GAAP!$G12<2,+GAAP!B12," " ) -> Silicon Valley Clean Water - FEP Improvements Project | C10: =IF(GAAP!$G12<2,+GAAP!J12," " ) -> 9667725.8 | D10: =IF(GAAP!$G12<2,+GAAP!M12," " ) -> 5301840.2 | E10: =IF(GAAP!$G12<2,+GAAP!C12," " ) -> 14969566 | F10: =IF(GAAP!$G12<2,+GAAP!F12," " ) -> 8406760.8 | G10: =IF(GAAP!$G12<2,+GAAP!L12," " ) -> 5432856.2 | H10: =IF(GAAP!$G12<2,+GAAP!D12," " ) -> 13839617 | I10: =IF(GAAP!$G12<2,+GAAP!E12," " ) -> 1129949 | J10: =IF(GAAP!$G12<2,+GAAP!G12," " ) -> 0.60744172 | K10: =IF(GAAP!$G12<2,+GAAP!H12," " ) -> 686378.17 | L10: =+GAAP!K12 -> 574586.8 | S10: =K10-'Bonus WIP'!K11 -> 0 | T10: =L10-'Bonus WIP'!L11 -> 0
A11: =+GAAP!A13 -> 51.1146 | B11: =IF(GAAP!$G13<2,+GAAP!B13," " ) -> National Carbon Technologies, LLC - Aymium Williams Production Facility | C11: =IF(GAAP!$G13<2,+GAAP!J13," " ) -> 60980234 | D11: =IF(GAAP!$G13<2,+GAAP!M13," " ) -> 0 | E11: =IF(GAAP!$G13<2,+GAAP!C13," " ) -> 60980234 | F11: =IF(GAAP!$G13<2,+GAAP!F13," " ) -> 40950686 | G11: =IF(GAAP!$G13<2,+GAAP!L13," " ) -> 3246167.5 | H11: =IF(GAAP!$G13<2,+GAAP!D13," " ) -> 44196854 | I11: =IF(GAAP!$G13<2,+GAAP!E13," " ) -> 16783380 | J11: =IF(GAAP!$G13<2,+GAAP!G13," " ) -> 0.92655207 | K11: =IF(GAAP!$G13<2,+GAAP!H13," " ) -> 15550675 | L11: =+GAAP!K13 -> 4478872.1 | S11: =K11-'Bonus WIP'!K12 -> -173716.62 | T11: =L11-'Bonus WIP'!L12 -> 173716.62
A12: =+GAAP!A14 -> 51.1151 | B12: =IF(GAAP!$G14<2,+GAAP!B14," " ) -> Sonoma Valley County Sanitation Dist. - Sonoma Valley Influent Effluent Upgrade | C12: =IF(GAAP!$G14<2,+GAAP!J14," " ) -> 5009265.2 | D12: =IF(GAAP!$G14<2,+GAAP!M14," " ) -> 5648934.8 | E12: =IF(GAAP!$G14<2,+GAAP!C14," " ) -> 10658200 | F12: =IF(GAAP!$G14<2,+GAAP!F14," " ) -> 4923435.2 | G12: =IF(GAAP!$G14<2,+GAAP!L14," " ) -> 5155916.8 | H12: =IF(GAAP!$G14<2,+GAAP!D14," " ) -> 10079352 | I12: =IF(GAAP!$G14<2,+GAAP!E14," " ) -> 578848 | J12: =IF(GAAP!$G14<2,+GAAP!G14," " ) -> 0.48846743 | K12: =IF(GAAP!$G14<2,+GAAP!H14," " ) -> 282748.4 | L12: =+GAAP!K14 -> -196918.37 | S12: =K12-'Bonus WIP'!K13 -> 0 | T12: =L12-'Bonus WIP'!L13 -> 0
A13: =+GAAP!A15 -> 51.1152 | B13: =IF(GAAP!$G15<2,+GAAP!B15," " ) -> Mozingo Construction Inc - ElD Sly Park Intertie Project | C13: =IF(GAAP!$G15<2,+GAAP!J15," " ) -> 15610649 | D13: =IF(GAAP!$G15<2,+GAAP!M15," " ) -> 4363840.3 | E13: =IF(GAAP!$G15<2,+GAAP!C15," " ) -> 19974489 | F13: =IF(GAAP!$G15<2,+GAAP!F15," " ) -> 13474809 | G13: =IF(GAAP!$G15<2,+GAAP!L15," " ) -> 5154139.8 | H13: =IF(GAAP!$G15<2,+GAAP!D15," " ) -> 18628948 | I13: =IF(GAAP!$G15<2,+GAAP!E15," " ) -> 1345541 | J13: =IF(GAAP!$G15<2,+GAAP!G15," " ) -> 0.72332631 | K13: =IF(GAAP!$G15<2,+GAAP!H15," " ) -> 973265.21 | L13: =+GAAP!K15 -> 1162575.3 | S13: =K13-'Bonus WIP'!K14 -> 0 | T13: =L13-'Bonus WIP'!L14 -> 0
A14: =+GAAP!A16 -> 51.1153 | B14: =IF(GAAP!$G16<2,+GAAP!B16," " ) -> Linda County Water Dist. - Aeration Blower Replacement | C14: =IF(GAAP!$G16<2,+GAAP!J16," " ) -> 549548.83 | D14: =IF(GAAP!$G16<2,+GAAP!M16," " ) -> 13275.85 | E14: =IF(GAAP!$G16<2,+GAAP!C16," " ) -> 562824.68 | F14: =IF(GAAP!$G16<2,+GAAP!F16," " ) -> 334550.81 | G14: =IF(GAAP!$G16<2,+GAAP!L16," " ) -> 119969.87 | H14: =IF(GAAP!$G16<2,+GAAP!D16," " ) -> 454520.68 | I14: =IF(GAAP!$G16<2,+GAAP!E16," " ) -> 108304 | J14: =IF(GAAP!$G16<2,+GAAP!G16," " ) -> 0.7360519 | K14: =IF(GAAP!$G16<2,+GAAP!H16," " ) -> 79717.365 | L14: =+GAAP!K16 -> 135280.66 | S14: =K14-'Bonus WIP'!K15 -> 0 | T14: =L14-'Bonus WIP'!L15 -> 0
A15: =+GAAP!A17 -> 51.1154 | B15: =IF(GAAP!$G17<2,+GAAP!B17," " ) -> Keyes Community Services Dist. - TCP Treatment Impvmts Wells 7,8,9,10 | C15: =IF(GAAP!$G17<2,+GAAP!J17," " ) -> 13340008 | D15: =IF(GAAP!$G17<2,+GAAP!M17," " ) -> 23827 | E15: =IF(GAAP!$G17<2,+GAAP!C17," " ) -> 13363835 | F15: =IF(GAAP!$G17<2,+GAAP!F17," " ) -> 11872343 | G15: =IF(GAAP!$G17<2,+GAAP!L17," " ) -> 616492.4 | H15: =IF(GAAP!$G17<2,+GAAP!D17," " ) -> 12488835 | I15: =IF(GAAP!$G17<2,+GAAP!E17," " ) -> 875000 | J15: =IF(GAAP!$G17<2,+GAAP!G17," " ) -> 0.95063652 | K15: =IF(GAAP!$G17<2,+GAAP!H17," " ) -> 831806.95 | L15: =+GAAP!K17 -> 635858.45 | S15: =K15-'Bonus WIP'!K16 -> 0 | T15: =L15-'Bonus WIP'!L16 -> 0
A16: =+GAAP!A18 -> 51.1158 | B16: =IF(GAAP!$G18<2,+GAAP!B18," " ) -> Schneider Electric - City of Ceres WWTP Phase 1- Schneider Electric | C16: =IF(GAAP!$G18<2,+GAAP!J18," " ) -> 32282 | D16: =IF(GAAP!$G18<2,+GAAP!M18," " ) -> 72164 | E16: =IF(GAAP!$G18<2,+GAAP!C18," " ) -> 104446 | F16: =IF(GAAP!$G18<2,+GAAP!F18," " ) -> 56960.69 | G16: =IF(GAAP!$G18<2,+GAAP!L18," " ) -> 47485.31 | H16: =IF(GAAP!$G18<2,+GAAP!D18," " ) -> 104446 | I16: =IF(GAAP!$G18<2,+GAAP!E18," " ) -> 0 | J16: =IF(GAAP!$G18<2,+GAAP!G18," " ) -> 0.54536019 | K16: =IF(GAAP!$G18<2,+GAAP!H18," " ) -> 0 | L16: =+GAAP!K18 -> -24678.69 | S16: =K16-'Bonus WIP'!K17 -> 0 | T16: =L16-'Bonus WIP'!L17 -> 0
A17: =+GAAP!A19 -> 51.1159 | B17: =IF(GAAP!$G19<2,+GAAP!B19," " ) -> El Dorado Irrigation Dist. - EID Reservoir A WTP Backwash-to-waste Valve Repalcement | C17: =IF(GAAP!$G19<2,+GAAP!J19," " ) -> 732995 | D17: =IF(GAAP!$G19<2,+GAAP!M19," " ) -> 466005 | E17: =IF(GAAP!$G19<2,+GAAP!C19," " ) -> 1199000 | F17: =IF(GAAP!$G19<2,+GAAP!F19," " ) -> 790051.12 | G17: =IF(GAAP!$G19<2,+GAAP!L19," " ) -> 289188.88 | H17: =IF(GAAP!$G19<2,+GAAP!D19," " ) -> 1079240 | I17: =IF(GAAP!$G19<2,+GAAP!E19," " ) -> 119760 | J17: =IF(GAAP!$G19<2,+GAAP!G19," " ) -> 0.73204396 | K17: =IF(GAAP!$G19<2,+GAAP!H19," " ) -> 87669.584 | L17: =+GAAP!K19 -> -144725.7 | S17: =K17-'Bonus WIP'!K18 -> 0 | T17: =L17-'Bonus WIP'!L18 -> 0
A18: =+GAAP!A20 -> 51.116 | B18: =IF(GAAP!$G20<2,+GAAP!B20," " ) -> City of Galt Public Works - Industrial WWTP Expansion | C18: =IF(GAAP!$G20<2,+GAAP!J20," " ) -> 223725 | D18: =IF(GAAP!$G20<2,+GAAP!M20," " ) -> 1533275 | E18: =IF(GAAP!$G20<2,+GAAP!C20," " ) -> 1757000 | F18: =IF(GAAP!$G20<2,+GAAP!F20," " ) -> 250518.05 | G18: =IF(GAAP!$G20<2,+GAAP!L20," " ) -> 1439481.9 | H18: =IF(GAAP!$G20<2,+GAAP!D20," " ) -> 1690000 | I18: =IF(GAAP!$G20<2,+GAAP!E20," " ) -> 67000 | J18: =IF(GAAP!$G20<2,+GAAP!G20," " ) -> 0.14823553 | K18: =IF(GAAP!$G20<2,+GAAP!H20," " ) -> 9931.7807 | L18: =+GAAP!K20 -> -36724.831 | S18: =K18-'Bonus WIP'!K19 -> 9931.7807 | T18: =L18-'Bonus WIP'!L19 -> -9931.7807
... A21: =+GAAP!A23 -> 51.1164 | B21: =IF(GAAP!$G23<2,+GAAP!B23," " ) -> CA Water Service Co. - Stockton Roofing | C21: =IF(GAAP!$G23<2,+GAAP!J23," " ) -> 0 | D21: =IF(GAAP!$G23<2,+GAAP!M23," " ) -> 387260 | E21: =IF(GAAP!$G23<2,+GAAP!C23," " ) -> 387260 | F21: =IF(GAAP!$G23<2,+GAAP!F23," " ) -> 4363.25 | G21: =IF(GAAP!$G23<2,+GAAP!L23," " ) -> 379023.75 | H21: =IF(GAAP!$G23<2,+GAAP!D23," " ) -> 383387 | I21: =IF(GAAP!$G23<2,+GAAP!E23," " ) -> 3873 | J21: =IF(GAAP!$G23<2,+GAAP!G23," " ) -> 0.011380798 | K21: =IF(GAAP!$G23<2,+GAAP!H23," " ) -> 0 | L21: =+GAAP!K23 -> -4363.25 | S21: =K21-'Bonus WIP'!K22 -> 0 | T21: =L21-'Bonus WIP'!L22 -> 0
A22: =+GAAP!A24 -> 51.1165 | B22: =IF(GAAP!$G24<2,+GAAP!B24," " ) -> City of Yuba City - WTP Aquifer Storage and Recovery Well No. 3 | C22: =IF(GAAP!$G24<2,+GAAP!J24," " ) -> 0 | D22: =IF(GAAP!$G24<2,+GAAP!M24," " ) -> 5304500 | E22: =IF(GAAP!$G24<2,+GAAP!C24," " ) -> 5304500 | F22: =IF(GAAP!$G24<2,+GAAP!F24," " ) -> 23330.33 | G22: =IF(GAAP!$G24<2,+GAAP!L24," " ) -> 4863112.7 | H22: =IF(GAAP!$G24<2,+GAAP!D24," " ) -> 4886443 | I22: =IF(GAAP!$G24<2,+GAAP!E24," " ) -> 418057 | J22: =IF(GAAP!$G24<2,+GAAP!G24," " ) -> 0.0047745016 | K22: =IF(GAAP!$G24<2,+GAAP!H24," " ) -> 0 | L22: =+GAAP!K24 -> -23330.33 | S22: =K22-'Bonus WIP'!#REF! -> #REF! | T22: =L22-'Bonus WIP'!#REF! -> #REF!
S23: =K23-'Bonus WIP'!K24 -> 0 | T23: =L23-'Bonus WIP'!L24 -> 0
A24: =+GAAP!A44 -> 52.8563 | B24: =IF(GAAP!$G44<2,+GAAP!B44," " ) -> City of Santa Cruz - Graham Hill WTP Facility Improvements - Phase 1 | C24: =IF(GAAP!$G44<2,+GAAP!J44," " ) -> 1134038.1 | D24: =IF(GAAP!$G44<2,+GAAP!M44," " ) -> 0 | E24: =IF(GAAP!$G44<2,+GAAP!C44," " ) -> 1134038.1 | F24: =IF(GAAP!$G44<2,+GAAP!F44," " ) -> 859077.05 | G24: =IF(GAAP!$G44<2,+GAAP!L44," " ) -> 0 | H24: =IF(GAAP!$G44<2,+GAAP!D44," " ) -> 859077.05 | I24: =IF(GAAP!$G44<2,+GAAP!E44," " ) -> 274961.08 | J24: =IF(GAAP!$G44<2,+GAAP!G44," " ) -> 1 | K24: =IF(GAAP!$G44<2,+GAAP!H44," " ) -> 274961.08 | L24: =+GAAP!K44 -> 0 | S24: =K24-'Bonus WIP'!K25 -> -18424.16 | T24: =L24-'Bonus WIP'!L25 -> 18424.16
A25: =+GAAP!A45 -> 52.8566 | B25: =IF(GAAP!$G45<2,+GAAP!B45," " ) -> City of Visalia - Water Reclamation Facility RPGS SCR System | C25: =IF(GAAP!$G45<2,+GAAP!J45," " ) -> 1242053 | D25: =IF(GAAP!$G45<2,+GAAP!M45," " ) -> 17345 | E25: =IF(GAAP!$G45<2,+GAAP!C45," " ) -> 1259398 | F25: =IF(GAAP!$G45<2,+GAAP!F45," " ) -> 1023821.1 | G25: =IF(GAAP!$G45<2,+GAAP!L45," " ) -> 5576.95 | H25: =IF(GAAP!$G45<2,+GAAP!D45," " ) -> 1029398 | I25: =IF(GAAP!$G45<2,+GAAP!E45," " ) -> 230000 | J25: =IF(GAAP!$G45<2,+GAAP!G45," " ) -> 0.99458232 | K25: =IF(GAAP!$G45<2,+GAAP!H45," " ) -> 228753.93 | L25: =+GAAP!K45 -> -10521.983 | S25: =K25-'Bonus WIP'!K26 -> 0 | T25: =L25-'Bonus WIP'!L26 -> 0
A26: =+GAAP!A46 -> 52.8586 | B26: =IF(GAAP!$G46<2,+GAAP!B46," " ) -> Tesoro Viejo MMWC- WTP/WWTP/RWSP Phase B Expansion - Phase 1 | C26: =IF(GAAP!$G46<2,+GAAP!J46," " ) -> 12611349 | D26: =IF(GAAP!$G46<2,+GAAP!M46," " ) -> 0 | E26: =IF(GAAP!$G46<2,+GAAP!C46," " ) -> 12611349 | F26: =IF(GAAP!$G46<2,+GAAP!F46," " ) -> 10565461 | G26: =IF(GAAP!$G46<2,+GAAP!L46," " ) -> 95888.26 | H26: =IF(GAAP!$G46<2,+GAAP!D46," " ) -> 10661349 | I26: =IF(GAAP!$G46<2,+GAAP!E46," " ) -> 1950000 | J26: =IF(GAAP!$G46<2,+GAAP!G46," " ) -> 0.99100599 | K26: =IF(GAAP!$G46<2,+GAAP!H46," " ) -> 1932461.7 | L26: =+GAAP!K46 -> 113426.58 | S26: =K26-'Bonus WIP'!K27 -> 0 | T26: =L26-'Bonus WIP'!L27 -> 0
A27: =+GAAP!A47 -> 52.8634 | B27: =IF(GAAP!$G47<2,+GAAP!B47," " ) -> City of Huron - Water Treatment Plant Imp. Phase 2 | C27: =IF(GAAP!$G47<2,+GAAP!J47," " ) -> 12576768 | D27: =IF(GAAP!$G47<2,+GAAP!M47," " ) -> 1315954.7 | E27: =IF(GAAP!$G47<2,+GAAP!C47," " ) -> 13892723 | F27: =IF(GAAP!$G47<2,+GAAP!F47," " ) -> 11707058 | G27: =IF(GAAP!$G47<2,+GAAP!L47," " ) -> 1483664.5 | H27: =IF(GAAP!$G47<2,+GAAP!D47," " ) -> 13190723 | I27: =IF(GAAP!$G47<2,+GAAP!E47," " ) -> 702000 | J27: =IF(GAAP!$G47<2,+GAAP!G47," " ) -> 0.88752212 | K27: =IF(GAAP!$G47<2,+GAAP!H47," " ) -> 623040.53 | L27: =+GAAP!K47 -> 246669.27 | S27: =K27-'Bonus WIP'!K28 -> 0 | T27: =L27-'Bonus WIP'!L28 -> 0
